Workbook

Sheet Tender Summary (SOT)
A1: HOLY BUILDERS SDN. BHD.
A2: BDA/CT/52/2026 - THE PROPOSED PROVISION AND LAYING OF WATERPROOFING MEMBRANE TO EXISTING ROOF BALCONIES AND ASSOCIATED WORKS AT WISMA BINTULU BUILDING (REMAINING WORKS)
A3: SUMMARY OF TENDER - PRICED | Tender date: 12 October 2026 | Validity: 90 days | Warranty: 2 years on waterproofing works
A5: Item | B5: Description | C5: Qty | D5: Unit | E5: Rate (RM) | F5: Amount (RM)
A6: 1.0 | B6: Preliminaries and Generally - specifications, conditions of contract, working hours, service elevator restrictions, safety & working at height, site cleanliness | D6: LUMP SUM | F6: ='Item Pricing'!I6 -> 471539.2
A7: 2.0 | B7: New Rain Water Down Pipe / Floor Trap
A8: 2.1 | B8: Coring work (110 mm dia.) to slab - identifying coring points, tests and PE-endorsed report | D8: LUMP SUM | F8: ='Item Pricing'!I7 -> 20005.28
A9: 2.2 | B9: Coring 110 mm dia. to floor slab / RC gutter wall for new floor traps / RWDP (1st floor gutter wall, 3rd, 4th, 5th, 6th floor slabs) | D9: LUMP SUM | F9: ='Item Pricing'!I8 -> 32260.14
A10: 2.3 | B10: Decommissioning of existing RWDP - dewatering, 4" PVC end caps, concrete to existing floor trap openings | D10: LUMP SUM | F10: ='Item Pricing'!I9 -> 9004.42
A11: 2.4 | B11: Supply and install new 110 mm dia. uPVC (SIRIM) RWDP / floor trap, 3.2 mm thk c/w tees, elbows, connections, clips, access through glazing (outlet to existing RC gutter at Level 1) | D11: LUMP SUM | F11: ='Item Pricing'!I10 -> 117104.37
A12: 3.0 | B12: Demolition and associated works - removing, carting away debris and making good | D12: LUMP SUM | F12: ='Item Pricing'!I11 -> 7526.4
A13: 3.1 | B13: Hacking work to existing cement screed and waterproofing (remaining portion) | D13: LUMP SUM | F13: ='Item Pricing'!I12 -> 119279.88
A14: 4.0 | B14: Screeding & Waterproofing System
A15: 4.1 | B15: Prepare surface, patching / repair of cracks, rectify ponding, thorough cleaning of RC slab | D15: LUMP SUM | F15: ='Item Pricing'!I13 -> 59158.48
A16: 4.2 | B16: Supply and apply 3 layer coat of SikaTop Seal-107 (MY) on entire RC slab - 3rd, 4th, 5th, 6th floor | D16: LUMP SUM | F16: ='Item Pricing'!I14 -> 164184.78
A17: 4.3 | B17: Cement and sand screeding to falls incl. forming new scupper drain, steel trowel finish, movement joints, BRC 610 mesh - 3rd, 4th, 5th, 6th floor | D17: LUMP SUM | F17: ='Item Pricing'!I15 -> 244254.12
A18: 4.4 | B18: Supply and apply 3 layers Sikalastic-632 R on new screed and scupper drain - 3rd, 4th, 5th, 6th floor | D18: LUMP SUM | F18: ='Item Pricing'!I16 -> 527230.89
A19: 4.5 | B19: Up-turns along wall and glass work along concrete balcony incl. raking columns, fittings & finishes to match existing - 3rd, 4th, 5th, 6th floor | D19: LUMP SUM | F19: ='Item Pricing'!I17 -> 80409.22
A20: 5.0 | B20: RC Gutter - high-pressure cleaning, removal of unwanted material, repair of cracks / honeycomb, 3 layers Sikalastic-632 R to gutter floor and wall | D20: LUMP SUM | F20: ='Item Pricing'!I18 -> 191246.73
A21: 6.0 | B21: Silicone seal - make good existing silicone along wall and glass at all balconies | D21: LUMP SUM | F21: ='Item Pricing'!I19 -> 16929.76
A22: 7.0 | B22: Provisional Items
A23: 7.1 | B23: Removal of existing defective ceiling incl. temporary dismantling of light fittings | C23: 2500 | D23: M2 | E23: =ROUND('Item Pricing'!I20,2) -> 7.81 | F23: =C23*E23 -> 19525
A24: 7.2 | B24: New prime flex 3 mm ceiling incl. reinstating light fittings, plastering joints | C24: 2500 | D24: M2 | E24: =ROUND('Item Pricing'!I21,2) -> 41.41 | F24: =C24*E24 -> 103525
A25: 7.3 | B25: Repair work to existing ceiling wooden structure | C25: 0.3 | D25: M3 | E25: =ROUND('Item Pricing'!I22,2) -> 6292.48 | F25: =C25*E25 -> 1887.744
A26: 7.4 | B26: Painting to repaired internal ceiling - alkali-resisting primer + 2 coats Dulux Pentalite | C26: 2500 | D26: M2 | E26: =ROUND('Item Pricing'!I23,2) -> 12.88 | F26: =C26*E26 -> 32200
A27: 7.5 | B27: Replace rusty / broken aluminium flashing with new 1.0 mm aluminium flashing c/w caulking | C27: 20 | D27: M2 | E27: =ROUND('Item Pricing'!I24,2) -> 204.29 | F27: =C27*E27 -> 4085.8
A28: 7.6 | B28: Grouting to repair cracks on existing slab | C28: 300 | D28: Point | E28: =ROUND('Item Pricing'!I25,2) -> 65.28 | F28: =C28*E28 -> 19584
A29: A | B29: SUB-TOTAL ITEMS 1.0 - 7.6 | F29: =SUM(F6:F28) -> 2240941.2
A30: B | B30: Insurance (CAR, workmen) & performance bond charges (% of A) | E30: ='Rates & Inputs'!$B$62 -> 0.012 | F30: =ROUND(F29*E30*(1+'Rates & Inputs'!$B$5),2) -> 34420.86
A31: 8. | B31: Provisional Sum for Sales and Service Tax (SST) | F31: ='Rates & Inputs'!$B$7 -> 80000
B32: TOTAL TO BE CARRIED TO FORM OF TENDER (RM) | F32: =ROUND(F29+F30+F31,0) -> 2355362
B34: PRICE ANALYSIS (for internal use - remove before submission)
B35: Net cost of works (materials + labour + plant), items 1.0-6.0 | F35: ='Item Pricing'!F26 -> 1580275.5
B36: of which: Materials | F36: ='Item Pricing'!C26 -> 871659.91
B37: of which: Labour (manpower) | F37: ='Item Pricing'!D26 -> 323686.48
B38: of which: Plant, logistics & preliminaries | F38: ='Item Pricing'!E26 -> 384929.13
B39: Warranty provision (2 years) | F39: ='Item Pricing'!G26 -> 29203.898
B40: Margin @ 28% (items 1.0-6.0) | F40: ='Item Pricing'!H26 -> 450654.24
B41: Tender price items 1.0-6.0 | F41: ='Item Pricing'!I26 -> 2060133.7
B42: Provisional items 7.1-7.6 (at tender rates) | F42: =SUM(F23:F28) -> 180807.54
...

Sheet Rates & Inputs
A1: HOLY BUILDERS SDN. BHD.
A2: RATES & INPUTS - BDA/CT/52/2026 WATERPROOFING, WISMA BINTULU (REMAINING WORKS)
A3: All yellow cells are inputs. Material prices are indicative Malaysian 2025/26 figures - replace with supplier quotations (Sika Kimia Sdn Bhd, local hardware) before submission.
A4: 1. COMMERCIAL SETTINGS
A5: Margin on net cost (overheads & profit) | B5: 0.28 | C5: % | D5: As instructed: 28%
A6: Warranty provision - 2 years defects / waterproofing warranty | B6: 0.03 | C6: % of net cost of waterproofing items | D6: Allowance for call-backs, re-coating, Sika extended warranty admin over 2 years; applied to items 4.2-4.5, 5.0, 6.0
A7: Provisional Sum for SST (fixed by BQ item 8) | B7: 80000 | C7: RM | D7: Carried as stated in the BQ
A8: Contract programme | B8: 16 | C8: weeks | D8: Assumed duration for preliminaries, supervision and plant hire
A9: Working days per week | B9: 6 | C9: days
A10: Material wastage allowance | B10: 0.18 | C10: % | D10: 18% top-up on all materials (as instructed)
A12: 2. MATERIAL PRICES (delivered to site, excl. SST)
A13: SikaTop Seal-107 (MY) 25 kg set | B13: 165 | C13: RM/set | D13: Sika Kimia / stockist quote required
A14: Sikalastic-632 R 21 kg pail | B14: 980 | C14: RM/pail
A15: Sikalastic U-Primer 14 kg pail | B15: 520 | C15: RM/pail
A16: Sika Reemat Premium 50 m² roll | B16: 480 | C16: RM/roll
A17: Sikaflex-11 FC+ 300 ml cartridge | B17: 26 | C17: RM/no.
A18: SikaTop-122 / MonoTop repair mortar 25 kg | B18: 125 | C18: RM/bag
A19: Sika Thinner C 5 L | B19: 65 | C19: RM/tin
A20: Portland cement 50 kg bag | B20: 23 | C20: RM/bag
A21: Washed sand (screed) | B21: 75 | C21: RM/m³ | D21: Delivered Bintulu
A22: BRC A6 / 610 mesh 2.4 x 4.8 m sheet | B22: 95 | C22: RM/sheet | D22: 11.52 m² per sheet
A23: Movement joint - bitumen board 10 mm + PU sealant | B23: 28 | C23: RM/m
A24: uPVC 110 mm Class D pipe 5.8 m (SIRIM) | B24: 68 | C24: RM/length
A25: uPVC 110 mm fittings (tee / elbow / coupling) average | B25: 28 | C25: RM/no.
A26: uPVC 110 mm pipe clip / bracket c/w anchor | B26: 12 | C26: RM/no.
A27: Floor trap 110 mm c/w stainless grating cover | B27: 85 | C27: RM/no.
A28: 4" PVC end cap | B28: 9 | C28: RM/no.
A29: Concrete / grout for sealing existing trap opening (per opening) | B29: 18 | C29: RM/no.
A30: Silicone sealant (neutral cure, as existing) 300 ml | B30: 22 | C30: RM/no. | D30: ~8 m per cartridge
A31: Aluminium flashing 1.0 mm sheet, fabricated | B31: 95 | C31: RM/m²
A32: Crack injection grout / epoxy per point | B32: 32 | C32: RM/point
A33: Prime flex 3 mm ceiling board (supply) | B33: 14 | C33: RM/m²
A34: Timber (treated) for ceiling structure | B34: 3200 | C34: RM/m³
A35: Dulux alkali-resisting primer + 2 coats Pentalite (material) | B35: 4.5 | C35: RM/m²
A36: Water & misc. consumables | B36: 0.5 | C36: RM/m²
A38: 3. LABOUR RATES (all-in, incl. EPF/SOCSO, levy, accommodation, transport)
A39: Site supervisor / foreman | B39: 280 | C39: RM/day
A40: Skilled waterproofing applicator (Sika-trained) | B40: 190 | C40: RM/day
A41: Screeder / mason | B41: 180 | C41: RM/day
A42: Plumber / coring operator | B42: 190 | C42: RM/day
...

Sheet Quantities
A1: HOLY BUILDERS SDN. BHD.
A2: QUANTITY TAKE-OFF (from CAD file Waterproofing_Contract.dwg and drawings BDA-MWS/BLD/1/2025)
A3: Plan areas measured from the drawing hatches; counts from drawing symbols. Yellow = inputs / assumptions to verify on site.
A4: 1. AREAS (m²)
A5: Floor | B5: Balcony slab incl. scupper drain (m²) | C5: of which scupper drain (m²) | D5: RC gutter plan area (m²) | E5: Remarks
A6: 3rd Floor | B6: 1068.32 | C6: 110.49 | D6: 0 | E6: Green floor hatch + yellow drain hatch, overlap removed
A7: 4th Floor | B7: 889.81 | C7: 96.79 | D7: 0
A8: 5th Floor | B8: 619.6 | C8: 72.02 | D8: 0
A9: 6th Floor | B9: 380.76 | C9: 58.6 | D9: 0 | E9: Drain ring lies inside the floor ring
A10: 1st Floor | B10: 0 | C10: 0 | D10: 309.84 | E10: Gutter 99.6 m OD x 1.0 m wide, 1.0 m deep (assumed)
A11: TOTAL | B11: =SUM(B6:B10) -> 2958.49 | C11: =SUM(C6:C10) -> 337.9 | D11: =SUM(D6:D10) -> 309.84
A13: 2. DERIVED QUANTITIES
A14: RC gutter depth (wall height) | B14: 1 | C14: m | D14: Assumed - not shown on drawing; verify on site
A15: RC gutter centre-line length | B15: =PI()*(99.6+97.6)/2 -> 309.76104 | C15: m | D15: Mean circumference
A16: RC gutter wall area (both sides) | B16: =2*Quantities!$B$15*Quantities!$B$14 -> 619.52207 | C16: m²
A17: RC gutter total coated area (floor + walls) | B17: =Quantities!$D$11+Quantities!$B$16 -> 929.36207 | C17: m² | D17: Item 5.0 Sikalastic-632 R
A18: Existing screed & waterproofing to hack (item 3.1) | B18: =Quantities!$B$11 -> 2958.49 | C18: m² | D18: Whole balcony slab 3rd-6th; BQ notes part already done - see % below
A19: Portion of hacking already completed by previous contractor | B19: 0 | C19: % | D19: Set from site inspection; 0% = price full hacking
A20: Existing screed thickness to remove (avg) | B20: 0.04 | C20: m | D20: Assumed 40 mm
A21: New screed average thickness to falls | B21: 0.05 | C21: m | D21: Assumed 50 mm avg (falls 1:80, min 30 mm at drain)
A22: New screed volume | B22: =Quantities!$B$11*Quantities!$B$21 -> 147.9245 | C22: m³
A23: Cement for 1:3 screed (incl. 18% wastage) | B23: =Quantities!$B$22*9*(1+'Rates & Inputs'!$B$10) -> 1570.9582 | C23: bags | D23: ~9 bags per m³
A24: Sand for screed (incl. wastage) | B24: =Quantities!$B$22*1.3*(1+'Rates & Inputs'!$B$10) -> 226.91618 | C24: m³ | D24: ~1.3 m³ per m³
A25: BRC 610 mesh sheets (incl. laps & wastage) | B25: =ROUNDUP(Quantities!$B$11/11.52*1.15*(1+'Rates & Inputs'!$B$10),0) -> 349 | C25: sheets
A26: Movement joints in screed | B26: =ROUNDUP(Quantities!$B$11/25,0)*5 -> 595 | C26: m | D26: Bays ~5 x 5 m: approx. 1 m of joint per 5 m²
A27: Up-turn length along walls / glass / raking columns (3rd-6th) | B27: 930 | C27: m | D27: Inner ring perimeters ~643 m + 24 raking columns x 3.0 m x 4 floors ~288 m
A28: Up-turn height | B28: 0.3 | C28: m | D28: Item 4.5
A29: Up-turn area (107 + 632 R + Reemat) | B29: =Quantities!$B$27*Quantities!$B$28 -> 279 | C29: m²
A30: Silicone joints along wall & glass at all balconies (item 6.0) | B30: 1300 | C30: m | D30: Inner perimeters 3rd-6th ~643 m x 2 lines (floor/wall + glass)
A32: 3. RWDP / CORING COUNTS (from drawing symbols)
A33: Floor | B33: Coring points - main RWDP through slab / gutter wall | C33: Coring points - new floor trap | D33: Existing floor trap covers to replace | E33: Remarks
A34: 1st Floor (RC gutter wall) | B34: 48 | C34: 0 | D34: 0 | E34: Yellow symbols on 2/11
A35: 3rd Floor | B35: 49 | C35: 49 | D35: 0 | E35: Red + blue symbols on 4/11
A36: 4th Floor | B36: 49 | C36: 48 | D36: 0 | E36: 5/11
A37: 5th Floor | B37: 1 | C37: 49 | D37: 0 | E37: 6/11
A38: 6th Floor | B38: 0 | C38: 0 | D38: 12 | E38: 7/11 - existing traps maintained, covers replaced
A39: TOTAL | B39: =SUM(B34:B38) -> 147 | C39: =SUM(C34:C38) -> 146 | D39: =SUM(D34:D38) -> 12
A40: Total new coring points (item 2.2) | B40: =Quantities!$B$39+Quantities!$C$39 -> 293 | C40: points
A41: Number of RWDP downpipes (level 5 to gutter) | B41: 49 | C41: no. | D41: One per column bay
A42: Pipe length per downpipe along raking column, L5 to L1 gutter | B42: 24 | C42: m | D42: 18 m vertical x 1.35 slope factor
...

Sheet Rate Build-up
A1: HOLY BUILDERS SDN. BHD.
A2: RATE BUILD-UP - NET COST BY BQ ITEM (materials, labour, plant & logistics)
A3: Every line is a formula linked to Quantities and Rates & Inputs. Type: M = material, L = labour, P = plant / logistics / preliminaries.
A5: BQ item | B5: Cost line | C5: Quantity | D5: Unit | E5: Rate (RM) | F5: Type | G5: Amount (RM) | H5: Basis
A6: 1.0 | B6: PRELIMINARIES AND GENERALLY
A7: 1.0 | B7: Site supervisor / foreman | C7: ='Rates & Inputs'!$B$8*'Rates & Inputs'!$B$9 -> 96 | D7: day | E7: ='Rates & Inputs'!$B$39 -> 280 | F7: L | G7: =C7*E7 -> 26880 | H7: Full programme
A8: 1.0 | B8: Site safety supervisor (working at height) | C8: ='Rates & Inputs'!$B$8*'Rates & Inputs'!$B$9 -> 96 | D8: day | E8: ='Rates & Inputs'!$B$44 -> 260 | F8: L | G8: =C8*E8 -> 24960 | H8: Full programme
A9: 1.0 | B9: Edge protection / mobile scaffold hire | C9: ='Rates & Inputs'!$B$8 -> 16 | D9: week | E9: ='Rates & Inputs'!$B$60 -> 2200 | F9: P | G9: =C9*E9 -> 35200
A10: 1.0 | B10: Site office, store, toilet, water & electricity | C10: ='Rates & Inputs'!$B$8 -> 16 | D10: week | E10: ='Rates & Inputs'!$B$61 -> 2400 | F10: P | G10: =C10*E10 -> 38400
A11: 1.0 | B11: Mixers, grinders, vacuum, small tools | C11: ='Rates & Inputs'!$B$8 -> 16 | D11: week | E11: ='Rates & Inputs'!$B$59 -> 900 | F11: P | G11: =C11*E11 -> 14400
A12: 1.0 | B12: HSE: PPE, harnesses, signage, barricades, lifting plan | C12: 1 | D12: lump | E12: ='Rates & Inputs'!$B$63 -> 9500 | F12: P | G12: =C12*E12 -> 9500
A13: 1.0 | B13: Mobilisation / demobilisation, hoarding, daily cleaning | C13: 1 | D13: lump | E13: ='Rates & Inputs'!$B$64 -> 12000 | F13: P | G13: =C13*E13 -> 12000 | H13: Debris cleared daily; work outside office hours where directed
A14: 1.0 | B14: Method statement, shop drawings, as-built, flood tests, Sika warranty | C14: 1 | D14: lump | E14: ='Rates & Inputs'!$B$65 -> 6500 | F14: P | G14: =C14*E14 -> 6500
A15: 1.0 | B15: Mobile crane 100 t - daily hire incl. operator | C15: =Quantities!$B$53 -> 20 | D15: day | E15: ='Rates & Inputs'!$B$49 -> 5800 | F15: P | G15: =C15*E15 -> 116000 | H15: Hoisting of materials and lowering of debris (no lifts for waste permitted)
A16: 1.0 | B16: Crane mobilisation / demobilisation | C16: ='Rates & Inputs'!$B$53 -> 6 | D16: no. | E16: ='Rates & Inputs'!$B$50 -> 8000 | F16: P | G16: =C16*E16 -> 48000
A17: 1.0 | B17: Riggers / signalmen (2 nos.) | C17: =2*Quantities!$B$53 -> 40 | D17: day | E17: ='Rates & Inputs'!$B$51 -> 150 | F17: P | G17: =C17*E17 -> 6000
A18: 1.0 | B18: Material delivery lorry trips | C18: =ROUNDUP(Quantities!$B$50/10,0) -> 47 | D18: trip | E18: ='Rates & Inputs'!$B$56 -> 650 | F18: P | G18: =C18*E18 -> 30550 | H18: 10 t per trip
A19: 1.0 | B19: Insurance (CAR, workmen) & bond charges - see Tender Summary | C19: 0 | D19: lump | E19: 0 | F19: P | G19: =C19*E19 -> 0 | H19: Calculated on the Tender Summary as % of contract sum
A20: 2.1 | B20: CORING WORK - IDENTIFYING CORING POINTS & TEST, PE REPORT
A21: 2.1 | B21: Professional Engineer assessment & endorsed report | C21: 1 | D21: lump | E21: ='Rates & Inputs'!$B$45 -> 9000 | F21: L | G21: =C21*E21 -> 9000
A22: 2.1 | B22: Rebar scanning (GPR / cover meter) at each coring point | C22: =Quantities!$B$40 -> 293 | D22: point | E22: ='Rates & Inputs'!$B$46 -> 15 | F22: L | G22: =C22*E22 -> 4395
A23: 2.1 | B23: Setting out of coring points (plumber + general worker) | C23: =Quantities!$B$40/40 -> 7.325 | D23: day | E23: ='Rates & Inputs'!$B$42+'Rates & Inputs'!$B$43 -> 305 | F23: L | G23: =C23*E23 -> 2234.125 | H23: 40 points per day
A24: 2.2 | B24: CORING 110 mm DIA. TO FLOOR SLAB / RC GUTTER WALL
A25: 2.2 | B25: Coring crew (2 men) - labour | C25: =Quantities!$B$40/'Rates & Inputs'!$B$76 -> 41.857143 | D25: man-day | E25: ='Rates & Inputs'!$B$42 -> 190 | F25: L | G25: =C25*E25 -> 7952.8571
A26: 2.2 | B26: Coring machine hire & diamond bit wear | C26: =Quantities!$B$40 -> 293 | D26: point | E26: ='Rates & Inputs'!$B$57 -> 22 | F26: P | G26: =C26*E26 -> 6446
A27: 2.2 | B27: Making good around cores - repair mortar | C27: =Quantities!$B$40*0.25*(1+'Rates & Inputs'!$B$10) -> 86.435 | D27: bag | E27: ='Rates & Inputs'!$B$18 -> 125 | F27: M | G27: =C27*E27 -> 10804.375 | H27: 0.25 bag per point
A28: 2.3 | B28: DECOMMISSIONING OF EXISTING RWDP
A29: 2.3 | B29: Dewatering existing RWDP (pump hire & labour) | C29: 4 | D29: day | E29: ='Rates & Inputs'!$B$43*2+180 -> 410 | F29: L | G29: =C29*E29 -> 1640 | H29: Pump hire RM 180/day + 2 workers
A30: 2.3 | B30: 4" PVC end caps | C30: =Quantities!$B$47*1.05 -> 153.3 | D30: no. | E30: ='Rates & Inputs'!$B$28 -> 9 | F30: M | G30: =C30*E30 -> 1379.7
A31: 2.3 | B31: Concrete / grout to existing floor trap openings | C31: =Quantities!$B$47 -> 146 | D31: no. | E31: ='Rates & Inputs'!$B$29 -> 18 | F31: M | G31: =C31*E31 -> 2628
A32: 2.3 | B32: Labour - cap and concrete existing traps | C32: =Quantities!$B$47/20 -> 7.3 | D32: man-day | E32: ='Rates & Inputs'!$B$42 -> 190 | F32: L | G32: =C32*E32 -> 1387 | H32: 20 traps per man-day
A33: 2.4 | B33: SUPPLY & INSTALL NEW 110 mm uPVC RWDP / FLOOR TRAP
A34: 2.4 | B34: uPVC 110 mm Class D pipe (SIRIM) 5.8 m lengths | C34: =Quantities!$B$44 -> 251 | D34: length | E34: ='Rates & Inputs'!$B$24 -> 68 | F34: M | G34: =C34*E34 -> 17068 | H34: Incl. 10% wastage in quantity
A35: 2.4 | B35: Fittings - tees, elbows, couplings | C35: =Quantities!$B$45 -> 495 | D35: no. | E35: ='Rates & Inputs'!$B$25 -> 28 | F35: M | G35: =C35*E35 -> 13860
A36: 2.4 | B36: Pipe clips / brackets c/w anchors | C36: =Quantities!$B$46 -> 970 | D36: no. | E36: ='Rates & Inputs'!$B$26 -> 12 | F36: M | G36: =C36*E36 -> 11640
A37: 2.4 | B37: Floor traps c/w gratings (new) + replacement covers at 6th floor | C37: =Quantities!$C$39+Quantities!$D$39 -> 158 | D37: no. | E37: ='Rates & Inputs'!$B$27 -> 85 | F37: M | G37: =C37*E37 -> 13430
A38: 2.4 | B38: Solvent cement, sealant at penetrations (Sikaflex) | C38: =(Quantities!$B$40)*0.5 -> 146.5 | D38: no. | E38: ='Rates & Inputs'!$B$17 -> 26 | F38: M | G38: =C38*E38 -> 3809 | H38: Half cartridge per penetration
A39: 2.4 | B39: Plumber labour - pipe installation on raking columns | C39: =Quantities!$B$43/'Rates & Inputs'!$B$77 -> 103.87143 | D39: man-day | E39: ='Rates & Inputs'!$B$42 -> 190 | F39: L | G39: =C39*E39 -> 19735.571 | H39: Incl. cutting access to glazing and connections to gutter
A40: 2.4 | B40: General worker assisting (1 per plumber) | C40: =Quantities!$B$43/'Rates & Inputs'!$B$77 -> 103.87143 | D40: man-day | E40: ='Rates & Inputs'!$B$43 -> 115 | F40: L | G40: =C40*E40 -> 11945.214
A41: 3.0 | B41: DEMOLITION AND ASSOCIATED WORKS
...

Sheet Item Pricing
A1: HOLY BUILDERS SDN. BHD.
A2: ITEM PRICING - NET COST, WARRANTY PROVISION, 28% MARGIN, TENDER PRICE
A3: Net costs are summed from the Rate Build-up by BQ item. Warranty % applies to waterproofing items only. Tender price = (net + warranty) x (1 + margin).
A5: BQ item | B5: Description | C5: Materials (RM) | D5: Labour (RM) | E5: Plant / logistics (RM) | F5: Net cost (RM) | G5: Warranty 2 yrs (RM) | H5: Margin 28% (RM) | I5: Tender price (RM) | J5: Price basis
A6: 1.0 | B6: Preliminaries and Generally | C6: =SUMIFS('Rate Build-up'!$G$6:$G$112,'Rate Build-up'!$A$6:$A$112,A6,'Rate Build-up'!$F$6:$F$112,"M") -> 0 | D6: =SUMIFS('Rate Build-up'!$G$6:$G$112,'Rate Build-up'!$A$6:$A$112,A6,'Rate Build-up'!$F$6:$F$112,"L") -> 51840 | E6: =SUMIFS('Rate Build-up'!$G$6:$G$112,'Rate Build-up'!$A$6:$A$112,A6,'Rate Build-up'!$F$6:$F$112,"P") -> 316550 | F6: =SUM(C6:E6) -> 368390 | G6: =0 -> 0 | H6: =(F6+G6)*'Rates & Inputs'!$B$5 -> 103149.2 | I6: =ROUND(F6+G6+H6,2) -> 471539.2 | J6: Lump sum
A7: 2.1 | B7: Coring - identify points, tests & PE report | C7: =SUMIFS('Rate Build-up'!$G$6:$G$112,'Rate Build-up'!$A$6:$A$112,A7,'Rate Build-up'!$F$6:$F$112,"M") -> 0 | D7: =SUMIFS('Rate Build-up'!$G$6:$G$112,'Rate Build-up'!$A$6:$A$112,A7,'Rate Build-up'!$F$6:$F$112,"L") -> 15629.125 | E7: =SUMIFS('Rate Build-up'!$G$6:$G$112,'Rate Build-up'!$A$6:$A$112,A7,'Rate Build-up'!$F$6:$F$112,"P") -> 0 | F7: =SUM(C7:E7) -> 15629.125 | G7: =0 -> 0 | H7: =(F7+G7)*'Rates & Inputs'!$B$5 -> 4376.155 | I7: =ROUND(F7+G7+H7,2) -> 20005.28 | J7: Lump sum
A8: 2.2 | B8: Coring 110 mm dia. to slab / RC gutter wall | C8: =SUMIFS('Rate Build-up'!$G$6:$G$112,'Rate Build-up'!$A$6:$A$112,A8,'Rate Build-up'!$F$6:$F$112,"M") -> 10804.375 | D8: =SUMIFS('Rate Build-up'!$G$6:$G$112,'Rate Build-up'!$A$6:$A$112,A8,'Rate Build-up'!$F$6:$F$112,"L") -> 7952.8571 | E8: =SUMIFS('Rate Build-up'!$G$6:$G$112,'Rate Build-up'!$A$6:$A$112,A8,'Rate Build-up'!$F$6:$F$112,"P") -> 6446 | F8: =SUM(C8:E8) -> 25203.232 | G8: =0 -> 0 | H8: =(F8+G8)*'Rates & Inputs'!$B$5 -> 7056.905 | I8: =ROUND(F8+G8+H8,2) -> 32260.14 | J8: Lump sum
A9: 2.3 | B9: Decommissioning of existing RWDP | C9: =SUMIFS('Rate Build-up'!$G$6:$G$112,'Rate Build-up'!$A$6:$A$112,A9,'Rate Build-up'!$F$6:$F$112,"M") -> 4007.7 | D9: =SUMIFS('Rate Build-up'!$G$6:$G$112,'Rate Build-up'!$A$6:$A$112,A9,'Rate Build-up'!$F$6:$F$112,"L") -> 3027 | E9: =SUMIFS('Rate Build-up'!$G$6:$G$112,'Rate Build-up'!$A$6:$A$112,A9,'Rate Build-up'!$F$6:$F$112,"P") -> 0 | F9: =SUM(C9:E9) -> 7034.7 | G9: =0 -> 0 | H9: =(F9+G9)*'Rates & Inputs'!$B$5 -> 1969.716 | I9: =ROUND(F9+G9+H9,2) -> 9004.42 | J9: Lump sum
A10: 2.4 | B10: Supply & install new 110 mm uPVC RWDP / floor trap | C10: =SUMIFS('Rate Build-up'!$G$6:$G$112,'Rate Build-up'!$A$6:$A$112,A10,'Rate Build-up'!$F$6:$F$112,"M") -> 59807 | D10: =SUMIFS('Rate Build-up'!$G$6:$G$112,'Rate Build-up'!$A$6:$A$112,A10,'Rate Build-up'!$F$6:$F$112,"L") -> 31680.786 | E10: =SUMIFS('Rate Build-up'!$G$6:$G$112,'Rate Build-up'!$A$6:$A$112,A10,'Rate Build-up'!$F$6:$F$112,"P") -> 0 | F10: =SUM(C10:E10) -> 91487.786 | G10: =0 -> 0 | H10: =(F10+G10)*'Rates & Inputs'!$B$5 -> 25616.58 | I10: =ROUND(F10+G10+H10,2) -> 117104.37 | J10: Lump sum
A11: 3.0 | B11: Demolition and associated works | C11: =SUMIFS('Rate Build-up'!$G$6:$G$112,'Rate Build-up'!$A$6:$A$112,A11,'Rate Build-up'!$F$6:$F$112,"M") -> 0 | D11: =SUMIFS('Rate Build-up'!$G$6:$G$112,'Rate Build-up'!$A$6:$A$112,A11,'Rate Build-up'!$F$6:$F$112,"L") -> 1380 | E11: =SUMIFS('Rate Build-up'!$G$6:$G$112,'Rate Build-up'!$A$6:$A$112,A11,'Rate Build-up'!$F$6:$F$112,"P") -> 4500 | F11: =SUM(C11:E11) -> 5880 | G11: =0 -> 0 | H11: =(F11+G11)*'Rates & Inputs'!$B$5 -> 1646.4 | I11: =ROUND(F11+G11+H11,2) -> 7526.4 | J11: Lump sum
A12: 3.1 | B12: Hacking work to existing cement screed | C12: =SUMIFS('Rate Build-up'!$G$6:$G$112,'Rate Build-up'!$A$6:$A$112,A12,'Rate Build-up'!$F$6:$F$112,"M") -> 0 | D12: =SUMIFS('Rate Build-up'!$G$6:$G$112,'Rate Build-up'!$A$6:$A$112,A12,'Rate Build-up'!$F$6:$F$112,"L") -> 48603.764 | E12: =SUMIFS('Rate Build-up'!$G$6:$G$112,'Rate Build-up'!$A$6:$A$112,A12,'Rate Build-up'!$F$6:$F$112,"P") -> 44583.645 | F12: =SUM(C12:E12) -> 93187.41 | G12: =0 -> 0 | H12: =(F12+G12)*'Rates & Inputs'!$B$5 -> 26092.475 | I12: =ROUND(F12+G12+H12,2) -> 119279.88 | J12: Lump sum
A13: 4.1 | B13: Prepare surface, patch / repair, rectify ponding, clean | C13: =SUMIFS('Rate Build-up'!$G$6:$G$112,'Rate Build-up'!$A$6:$A$112,A13,'Rate Build-up'!$F$6:$F$112,"M") -> 21203.498 | D13: =SUMIFS('Rate Build-up'!$G$6:$G$112,'Rate Build-up'!$A$6:$A$112,A13,'Rate Build-up'!$F$6:$F$112,"L") -> 16060.374 | E13: =SUMIFS('Rate Build-up'!$G$6:$G$112,'Rate Build-up'!$A$6:$A$112,A13,'Rate Build-up'!$F$6:$F$112,"P") -> 7607.5457 | F13: =SUM(C13:E13) -> 44871.418 | G13: =F13*'Rates & Inputs'!$B$6 -> 1346.1425 | H13: =(F13+G13)*'Rates & Inputs'!$B$5 -> 12940.917 | I13: =ROUND(F13+G13+H13,2) -> 59158.48 | J13: Lump sum
A14: 4.2 | B14: 3 coats SikaTop Seal-107 (MY) on entire RC slab | C14: =SUMIFS('Rate Build-up'!$G$6:$G$112,'Rate Build-up'!$A$6:$A$112,A14,'Rate Build-up'!$F$6:$F$112,"M") -> 105264.24 | D14: =SUMIFS('Rate Build-up'!$G$6:$G$112,'Rate Build-up'!$A$6:$A$112,A14,'Rate Build-up'!$F$6:$F$112,"L") -> 19269.112 | E14: =SUMIFS('Rate Build-up'!$G$6:$G$112,'Rate Build-up'!$A$6:$A$112,A14,'Rate Build-up'!$F$6:$F$112,"P") -> 0 | F14: =SUM(C14:E14) -> 124533.36 | G14: =F14*'Rates & Inputs'!$B$6 -> 3736.0007 | H14: =(F14+G14)*'Rates & Inputs'!$B$5 -> 35915.42 | I14: =ROUND(F14+G14+H14,2) -> 164184.78 | J14: Lump sum
A15: 4.3 | B15: Cement & sand screed to falls c/w scupper drain, BRC 610 | C15: =SUMIFS('Rate Build-up'!$G$6:$G$112,'Rate Build-up'!$A$6:$A$112,A15,'Rate Build-up'!$F$6:$F$112,"M") -> 105924.24 | D15: =SUMIFS('Rate Build-up'!$G$6:$G$112,'Rate Build-up'!$A$6:$A$112,A15,'Rate Build-up'!$F$6:$F$112,"L") -> 79341.323 | E15: =SUMIFS('Rate Build-up'!$G$6:$G$112,'Rate Build-up'!$A$6:$A$112,A15,'Rate Build-up'!$F$6:$F$112,"P") -> 0 | F15: =SUM(C15:E15) -> 185265.56 | G15: =F15*'Rates & Inputs'!$B$6 -> 5557.9669 | H15: =(F15+G15)*'Rates & Inputs'!$B$5 -> 53430.589 | I15: =ROUND(F15+G15+H15,2) -> 244254.12 | J15: Lump sum
A16: 4.4 | B16: 3 layers Sikalastic-632 R on screed & scupper drain | C16: =SUMIFS('Rate Build-up'!$G$6:$G$112,'Rate Build-up'!$A$6:$A$112,A16,'Rate Build-up'!$F$6:$F$112,"M") -> 377020 | D16: =SUMIFS('Rate Build-up'!$G$6:$G$112,'Rate Build-up'!$A$6:$A$112,A16,'Rate Build-up'!$F$6:$F$112,"L") -> 22882.071 | E16: =SUMIFS('Rate Build-up'!$G$6:$G$112,'Rate Build-up'!$A$6:$A$112,A16,'Rate Build-up'!$F$6:$F$112,"P") -> 0 | F16: =SUM(C16:E16) -> 399902.07 | G16: =F16*'Rates & Inputs'!$B$6 -> 11997.062 | H16: =(F16+G16)*'Rates & Inputs'!$B$5 -> 115331.76 | I16: =ROUND(F16+G16+H16,2) -> 527230.89 | J16: Lump sum
A17: 4.5 | B17: Up-turns along wall, glass & raking columns | C17: =SUMIFS('Rate Build-up'!$G$6:$G$112,'Rate Build-up'!$A$6:$A$112,A17,'Rate Build-up'!$F$6:$F$112,"M") -> 55100 | D17: =SUMIFS('Rate Build-up'!$G$6:$G$112,'Rate Build-up'!$A$6:$A$112,A17,'Rate Build-up'!$F$6:$F$112,"L") -> 5890 | E17: =SUMIFS('Rate Build-up'!$G$6:$G$112,'Rate Build-up'!$A$6:$A$112,A17,'Rate Build-up'!$F$6:$F$112,"P") -> 0 | F17: =SUM(C17:E17) -> 60990 | G17: =F17*'Rates & Inputs'!$B$6 -> 1829.7 | H17: =(F17+G17)*'Rates & Inputs'!$B$5 -> 17589.516 | I17: =ROUND(F17+G17+H17,2) -> 80409.22 | J17: Lump sum
A18: 5.0 | B18: RC Gutter - clean, repair, 3 layers Sikalastic-632 R | C18: =SUMIFS('Rate Build-up'!$G$6:$G$112,'Rate Build-up'!$A$6:$A$112,A18,'Rate Build-up'!$F$6:$F$112,"M") -> 126744.85 | D18: =SUMIFS('Rate Build-up'!$G$6:$G$112,'Rate Build-up'!$A$6:$A$112,A18,'Rate Build-up'!$F$6:$F$112,"L") -> 13072.926 | E18: =SUMIFS('Rate Build-up'!$G$6:$G$112,'Rate Build-up'!$A$6:$A$112,A18,'Rate Build-up'!$F$6:$F$112,"P") -> 5241.9357 | F18: =SUM(C18:E18) -> 145059.72 | G18: =F18*'Rates & Inputs'!$B$6 -> 4351.7915 | H18: =(F18+G18)*'Rates & Inputs'!$B$5 -> 41835.222 | I18: =ROUND(F18+G18+H18,2) -> 191246.73 | J18: Lump sum
A19: 6.0 | B19: Silicone seal to wall & glass | C19: =SUMIFS('Rate Build-up'!$G$6:$G$112,'Rate Build-up'!$A$6:$A$112,A19,'Rate Build-up'!$F$6:$F$112,"M") -> 5784 | D19: =SUMIFS('Rate Build-up'!$G$6:$G$112,'Rate Build-up'!$A$6:$A$112,A19,'Rate Build-up'!$F$6:$F$112,"L") -> 7057.1429 | E19: =SUMIFS('Rate Build-up'!$G$6:$G$112,'Rate Build-up'!$A$6:$A$112,A19,'Rate Build-up'!$F$6:$F$112,"P") -> 0 | F19: =SUM(C19:E19) -> 12841.143 | G19: =F19*'Rates & Inputs'!$B$6 -> 385.23429 | H19: =(F19+G19)*'Rates & Inputs'!$B$5 -> 3703.3856 | I19: =ROUND(F19+G19+H19,2) -> 16929.76 | J19: Lump sum
A20: 7.1 | B20: Prov. - removal of defective ceiling (rate per m²) | C20: =SUMIFS('Rate Build-up'!$G$6:$G$112,'Rate Build-up'!$A$6:$A$112,A20,'Rate Build-up'!$F$6:$F$112,"M") -> 0 | D20: =SUMIFS('Rate Build-up'!$G$6:$G$112,'Rate Build-up'!$A$6:$A$112,A20,'Rate Build-up'!$F$6:$F$112,"L") -> 4.6 | E20: =SUMIFS('Rate Build-up'!$G$6:$G$112,'Rate Build-up'!$A$6:$A$112,A20,'Rate Build-up'!$F$6:$F$112,"P") -> 1.5 | F20: =SUM(C20:E20) -> 6.1 | G20: =0 -> 0 | H20: =(F20+G20)*'Rates & Inputs'!$B$5 -> 1.708 | I20: =ROUND(F20+G20+H20,2) -> 7.81 | J20: Rate per unit (provisional)
A21: 7.2 | B21: Prov. - new prime flex 3 mm ceiling (rate per m²) | C21: =SUMIFS('Rate Build-up'!$G$6:$G$112,'Rate Build-up'!$A$6:$A$112,A21,'Rate Build-up'!$F$6:$F$112,"M") -> 16.52 | D21: =SUMIFS('Rate Build-up'!$G$6:$G$112,'Rate Build-up'!$A$6:$A$112,A21,'Rate Build-up'!$F$6:$F$112,"L") -> 15.833333 | E21: =SUMIFS('Rate Build-up'!$G$6:$G$112,'Rate Build-up'!$A$6:$A$112,A21,'Rate Build-up'!$F$6:$F$112,"P") -> 0 | F21: =SUM(C21:E21) -> 32.353333 | G21: =0 -> 0 | H21: =(F21+G21)*'Rates & Inputs'!$B$5 -> 9.0589333 | I21: =ROUND(F21+G21+H21,2) -> 41.41 | J21: Rate per unit (provisional)
A22: 7.3 | B22: Prov. - repair ceiling wooden structure (rate per m³) | C22: =SUMIFS('Rate Build-up'!$G$6:$G$112,'Rate Build-up'!$A$6:$A$112,A22,'Rate Build-up'!$F$6:$F$112,"M") -> 3776 | D22: =SUMIFS('Rate Build-up'!$G$6:$G$112,'Rate Build-up'!$A$6:$A$112,A22,'Rate Build-up'!$F$6:$F$112,"L") -> 1140 | E22: =SUMIFS('Rate Build-up'!$G$6:$G$112,'Rate Build-up'!$A$6:$A$112,A22,'Rate Build-up'!$F$6:$F$112,"P") -> 0 | F22: =SUM(C22:E22) -> 4916 | G22: =0 -> 0 | H22: =(F22+G22)*'Rates & Inputs'!$B$5 -> 1376.48 | I22: =ROUND(F22+G22+H22,2) -> 6292.48 | J22: Rate per unit (provisional)
A23: 7.4 | B23: Prov. - painting ceiling (rate per m²) | C23: =SUMIFS('Rate Build-up'!$G$6:$G$112,'Rate Build-up'!$A$6:$A$112,A23,'Rate Build-up'!$F$6:$F$112,"M") -> 5.31 | D23: =SUMIFS('Rate Build-up'!$G$6:$G$112,'Rate Build-up'!$A$6:$A$112,A23,'Rate Build-up'!$F$6:$F$112,"L") -> 4.75 | E23: =SUMIFS('Rate Build-up'!$G$6:$G$112,'Rate Build-up'!$A$6:$A$112,A23,'Rate Build-up'!$F$6:$F$112,"P") -> 0 | F23: =SUM(C23:E23) -> 10.06 | G23: =0 -> 0 | H23: =(F23+G23)*'Rates & Inputs'!$B$5 -> 2.8168 | I23: =ROUND(F23+G23+H23,2) -> 12.88 | J23: Rate per unit (provisional)
A24: 7.5 | B24: Prov. - aluminium flashing (rate per m²) | C24: =SUMIFS('Rate Build-up'!$G$6:$G$112,'Rate Build-up'!$A$6:$A$112,A24,'Rate Build-up'!$F$6:$F$112,"M") -> 112.1 | D24: =SUMIFS('Rate Build-up'!$G$6:$G$112,'Rate Build-up'!$A$6:$A$112,A24,'Rate Build-up'!$F$6:$F$112,"L") -> 47.5 | E24: =SUMIFS('Rate Build-up'!$G$6:$G$112,'Rate Build-up'!$A$6:$A$112,A24,'Rate Build-up'!$F$6:$F$112,"P") -> 0 | F24: =SUM(C24:E24) -> 159.6 | G24: =0 -> 0 | H24: =(F24+G24)*'Rates & Inputs'!$B$5 -> 44.688 | I24: =ROUND(F24+G24+H24,2) -> 204.29 | J24: Rate per unit (provisional)
A25: 7.6 | B25: Prov. - grouting to cracks (rate per point) | C25: =SUMIFS('Rate Build-up'!$G$6:$G$112,'Rate Build-up'!$A$6:$A$112,A25,'Rate Build-up'!$F$6:$F$112,"M") -> 32 | D25: =SUMIFS('Rate Build-up'!$G$6:$G$112,'Rate Build-up'!$A$6:$A$112,A25,'Rate Build-up'!$F$6:$F$112,"L") -> 19 | E25: =SUMIFS('Rate Build-up'!$G$6:$G$112,'Rate Build-up'!$A$6:$A$112,A25,'Rate Build-up'!$F$6:$F$112,"P") -> 0 | F25: =SUM(C25:E25) -> 51 | G25: =0 -> 0 | H25: =(F25+G25)*'Rates & Inputs'!$B$5 -> 14.28 | I25: =ROUND(F25+G25+H25,2) -> 65.28 | J25: Rate per unit (provisional)
A26: TOTAL (lump-sum items 1.0 - 6.0 only) | C26: =SUM(C6:C19) -> 871659.91 | D26: =SUM(D6:D19) -> 323686.48 | E26: =SUM(E6:E19) -> 384929.13 | F26: =SUM(F6:F19) -> 1580275.5 | G26: =SUM(G6:G19) -> 29203.898 | H26: =SUM(H6:H19) -> 450654.24 | I26: =SUM(I6:I19) -> 2060133.7
A28: Notes:
A29: 1. Margin (28%) and the 2-year warranty provision are inputs on the Rates & Inputs sheet. Insurance & bond charges are added on the Tender Summary as a % of the contract sum.
A30: 2. Provisional items 7.1-7.6 are priced as unit rates (incl. margin) and multiplied by the BQ provisional quantities on the Tender Summary.
A31: 3. Item 3.1: the BQ states part of the hacking has been carried out - set the completed % on the Quantities sheet after the site visit.
