Workbook

Sheet Load Schedule
A1: WAREHOUSE ELECTRICAL LOAD SCHEDULE & CONSUMPTION CALCULATOR
A2: ="Site: "&'Settings & Tariff'!$B$5&" | Incoming: "&'Settings & Tariff'!$B$6&"-phase "&'Settings & Tariff'!$B$7&" A, "&'Settings & Tariff'!$B$8&" V | Capacity "&TEXT('Settings & Tariff'!$B$12,"0.0")&" kVA / "&TEXT('Settings & Tariff'!$B$13,"0.0")&" kW" -> Site: Holy Builders Warehouse, Bintulu | Incoming: 3-phase 60 A, 415 V | Capacity 43.1 kVA / 36.7 kW
A3: Key in the yellow cells only: Type (dropdown), Watts each, Qty, Hours/day, Days/month, Load %, Phase, Peak (Y/N). All other columns calculate.
A5: PHASE BALANCE (A) | B5: Phase R | D5: Phase Y | F5: Phase B | H5: Phase check | K5: Connected load (kW) | L5: Est. max demand (kW) | M5: Current/phase (A) | N5: % of breaker | O5: Monthly kWh | P5: Monthly bill (RM)
A6: Peak current per phase | B6: =(SUMIFS(M10:M39,J10:J39,"R")*1000/('Settings & Tariff'!$B$8/SQRT(3)*'Settings & Tariff'!$B$9)+SUMIFS(M10:M39,J10:J39,"3P")*1000/(SQRT(3)*'Settings & Tariff'!$B$8*'Settings & Tariff'!$B$9))*'Settings & Tariff'!$B$10 -> 24.943496 | D6: =(SUMIFS(M10:M39,J10:J39,"Y")*1000/('Settings & Tariff'!$B$8/SQRT(3)*'Settings & Tariff'!$B$9)+SUMIFS(M10:M39,J10:J39,"3P")*1000/(SQRT(3)*'Settings & Tariff'!$B$8*'Settings & Tariff'!$B$9))*'Settings & Tariff'!$B$10 -> 23.961468 | F6: =(SUMIFS(M10:M39,J10:J39,"B")*1000/('Settings & Tariff'!$B$8/SQRT(3)*'Settings & Tariff'!$B$9)+SUMIFS(M10:M39,J10:J39,"3P")*1000/(SQRT(3)*'Settings & Tariff'!$B$8*'Settings & Tariff'!$B$9))*'Settings & Tariff'!$B$10 -> 28.950167 | H6: =IF(MAX(B6,D6,F6)>'Settings & Tariff'!$B$7,"Phase overloaded",IF(B7>0.2,"Rebalance phases","Balanced")) -> Balanced | K6: SUPPLY CHECK: | L6: =IF(N7>1,"OVERLOADED - demand exceeds "&'Settings & Tariff'!$B$7&" A main breaker. Reduce peak loads or apply for a larger supply.",IF(M7>'Settings & Tariff'!$B$14,"NEAR LIMIT - above "&'Settings & Tariff'!$B$11*100&"% of breaker. Stagger loads / balance phases.","OK - "&TEXT('Settings & Tariff'!$B$13-L7,"0.0")&" kW headroom on the "&'Settings & Tariff'!$B$7&" A supply.")) -> OK - 20.8 kW headroom on the 60 A supply.
A7: Imbalance | B7: =IF(MAX(B6,D6,F6)=0,0,(MAX(B6,D6,F6)-MIN(B6,D6,F6))/MAX(B6,D6,F6)) -> 0.17232022 | C7: ← keep below 20% | K7: =SUM(L10:L39) -> 29.39 | L7: =SUM(M10:M39)*'Settings & Tariff'!$B$10 -> 15.856 | M7: =IF('Settings & Tariff'!$B$6=3,L7*1000/(SQRT(3)*'Settings & Tariff'!$B$8*'Settings & Tariff'!$B$9),L7*1000/('Settings & Tariff'!$B$8*'Settings & Tariff'!$B$9)) -> 25.95171 | N7: =M7/'Settings & Tariff'!$B$7 -> 0.43252851 | O7: =SUM(O10:O39) -> 4793.84 | P7: =IF('Settings & Tariff'!$B$17="C2",MAX(O7*'Settings & Tariff'!$B$18/100+L7*'Settings & Tariff'!$B$19,L7*'Settings & Tariff'!$B$19),MAX('Settings & Tariff'!$F$32,'Settings & Tariff'!$B$20))*(1+'Settings & Tariff'!$B$21) -> 1514.0288
A9: No | B9: Equipment / circuit description | C9: Type | D9: Watts each (W) | E9: Qty | F9: Hours / day | G9: Days / month | H9: Load % | I9: Peak (Y/N) | J9: Phase (R/Y/B/3P) | K9: kWh/day | L9: Connected kW | M9: Demand kW | N9: Current (A) | O9: Monthly kWh | P9: Monthly cost (RM) | Q9: Remarks
A10: 1 | B10: LED spotlights - signage & front | C10: Spotlight | D10: 50 | E10: 10 | F10: 12 | G10: 30 | H10: 1 | I10: Y | J10: R | K10: =IF(B10="","",D10*E10*H10*F10/1000) -> 6 | L10: =IF(B10="","",D10*E10/1000) -> 0.5 | M10: =IF(B10="","",IF(UPPER(I10)="Y",L10*H10,0)) -> 0.5 | N10: =IF(B10="","",IF(J10="3P",L10*H10*1000/(SQRT(3)*'Settings & Tariff'!$B$8*'Settings & Tariff'!$B$9),L10*H10*1000/('Settings & Tariff'!$B$8/SQRT(3)*'Settings & Tariff'!$B$9))) -> 2.4550685 | O10: =IF(B10="","",K10*G10) -> 180 | P10: =IF(B10="","",IF($O$7=0,0,O10/$O$7*$P$7)) -> 56.849036 | Q10: Dusk to midnight
A11: 2 | B11: LED high-bay lights - warehouse | C11: Lighting | D11: 150 | E11: 40 | F11: 10 | G11: 26 | H11: 1 | I11: Y | J11: 3P | K11: =IF(B11="","",D11*E11*H11*F11/1000) -> 60 | L11: =IF(B11="","",D11*E11/1000) -> 6 | M11: =IF(B11="","",IF(UPPER(I11)="Y",L11*H11,0)) -> 6 | N11: =IF(B11="","",IF(J11="3P",L11*H11*1000/(SQRT(3)*'Settings & Tariff'!$B$8*'Settings & Tariff'!$B$9),L11*H11*1000/('Settings & Tariff'!$B$8/SQRT(3)*'Settings & Tariff'!$B$9))) -> 9.8202739 | O11: =IF(B11="","",K11*G11) -> 1560 | P11: =IF(B11="","",IF($O$7=0,0,O11/$O$7*$P$7)) -> 492.69165 | Q11: Spread over R/Y/B circuits
A12: 3 | B12: LED tube lights - office & store | C12: Lighting | D12: 18 | E12: 30 | F12: 9 | G12: 26 | H12: 1 | I12: Y | J12: R | K12: =IF(B12="","",D12*E12*H12*F12/1000) -> 4.86 | L12: =IF(B12="","",D12*E12/1000) -> 0.54 | M12: =IF(B12="","",IF(UPPER(I12)="Y",L12*H12,0)) -> 0.54 | N12: =IF(B12="","",IF(J12="3P",L12*H12*1000/(SQRT(3)*'Settings & Tariff'!$B$8*'Settings & Tariff'!$B$9),L12*H12*1000/('Settings & Tariff'!$B$8/SQRT(3)*'Settings & Tariff'!$B$9))) -> 2.651474 | O12: =IF(B12="","",K12*G12) -> 126.36 | P12: =IF(B12="","",IF($O$7=0,0,O12/$O$7*$P$7)) -> 39.908023
A13: 4 | B13: Air-cond 2.5 hp - office 1 | C13: Air-cond | D13: 2300 | E13: 1 | F13: 9 | G13: 26 | H13: 0.7 | I13: Y | J13: R | K13: =IF(B13="","",D13*E13*H13*F13/1000) -> 14.49 | L13: =IF(B13="","",D13*E13/1000) -> 2.3 | M13: =IF(B13="","",IF(UPPER(I13)="Y",L13*H13,0)) -> 1.61 | N13: =IF(B13="","",IF(J13="3P",L13*H13*1000/(SQRT(3)*'Settings & Tariff'!$B$8*'Settings & Tariff'!$B$9),L13*H13*1000/('Settings & Tariff'!$B$8/SQRT(3)*'Settings & Tariff'!$B$9))) -> 7.9053205 | O13: =IF(B13="","",K13*G13) -> 376.74 | P13: =IF(B13="","",IF($O$7=0,0,O13/$O$7*$P$7)) -> 118.98503 | Q13: Compressor cycling ~70%
A14: 5 | B14: Air-cond 2.0 hp - office 2 | C14: Air-cond | D14: 1800 | E14: 1 | F14: 9 | G14: 26 | H14: 0.7 | I14: Y | J14: B | K14: =IF(B14="","",D14*E14*H14*F14/1000) -> 11.34 | L14: =IF(B14="","",D14*E14/1000) -> 1.8 | M14: =IF(B14="","",IF(UPPER(I14)="Y",L14*H14,0)) -> 1.26 | N14: =IF(B14="","",IF(J14="3P",L14*H14*1000/(SQRT(3)*'Settings & Tariff'!$B$8*'Settings & Tariff'!$B$9),L14*H14*1000/('Settings & Tariff'!$B$8/SQRT(3)*'Settings & Tariff'!$B$9))) -> 6.1867726 | O14: =IF(B14="","",K14*G14) -> 294.84 | P14: =IF(B14="","",IF($O$7=0,0,O14/$O$7*$P$7)) -> 93.118721
A15: 6 | B15: Air-cond 1.5 hp - guard house | C15: Air-cond | D15: 1300 | E15: 1 | F15: 12 | G15: 30 | H15: 0.7 | I15: Y | J15: B | K15: =IF(B15="","",D15*E15*H15*F15/1000) -> 10.92 | L15: =IF(B15="","",D15*E15/1000) -> 1.3 | M15: =IF(B15="","",IF(UPPER(I15)="Y",L15*H15,0)) -> 0.91 | N15: =IF(B15="","",IF(J15="3P",L15*H15*1000/(SQRT(3)*'Settings & Tariff'!$B$8*'Settings & Tariff'!$B$9),L15*H15*1000/('Settings & Tariff'!$B$8/SQRT(3)*'Settings & Tariff'!$B$9))) -> 4.4682246 | O15: =IF(B15="","",K15*G15) -> 327.6 | P15: =IF(B15="","",IF($O$7=0,0,O15/$O$7*$P$7)) -> 103.46525
A16: 7 | B16: 13 A sockets - office general (per outlet) | C16: 13A Socket | D16: 200 | E16: 12 | F16: 9 | G16: 26 | H16: 0.5 | I16: Y | J16: B | K16: =IF(B16="","",D16*E16*H16*F16/1000) -> 10.8 | L16: =IF(B16="","",D16*E16/1000) -> 2.4 | M16: =IF(B16="","",IF(UPPER(I16)="Y",L16*H16,0)) -> 1.2 | N16: =IF(B16="","",IF(J16="3P",L16*H16*1000/(SQRT(3)*'Settings & Tariff'!$B$8*'Settings & Tariff'!$B$9),L16*H16*1000/('Settings & Tariff'!$B$8/SQRT(3)*'Settings & Tariff'!$B$9))) -> 5.8921643 | O16: =IF(B16="","",K16*G16) -> 280.8 | P16: =IF(B16="","",IF($O$7=0,0,O16/$O$7*$P$7)) -> 88.684497 | Q16: Computers, printers, chargers
A17: 8 | B17: 13 A socket - pantry kettle & fridge | C17: 13A Socket | D17: 2000 | E17: 1 | F17: 2 | G17: 26 | H17: 1 | I17: N | J17: R | K17: =IF(B17="","",D17*E17*H17*F17/1000) -> 4 | L17: =IF(B17="","",D17*E17/1000) -> 2 | M17: =IF(B17="","",IF(UPPER(I17)="Y",L17*H17,0)) -> 0 | N17: =IF(B17="","",IF(J17="3P",L17*H17*1000/(SQRT(3)*'Settings & Tariff'!$B$8*'Settings & Tariff'!$B$9),L17*H17*1000/('Settings & Tariff'!$B$8/SQRT(3)*'Settings & Tariff'!$B$9))) -> 9.8202739 | O17: =IF(B17="","",K17*G17) -> 104 | P17: =IF(B17="","",IF($O$7=0,0,O17/$O$7*$P$7)) -> 32.84611
A18: 9 | B18: 13 A sockets - warehouse power tools | C18: 13A Socket | D18: 1000 | E18: 4 | F18: 3 | G18: 26 | H18: 0.6 | I18: Y | J18: Y | K18: =IF(B18="","",D18*E18*H18*F18/1000) -> 7.2 | L18: =IF(B18="","",D18*E18/1000) -> 4 | M18: =IF(B18="","",IF(UPPER(I18)="Y",L18*H18,0)) -> 2.4 | N18: =IF(B18="","",IF(J18="3P",L18*H18*1000/(SQRT(3)*'Settings & Tariff'!$B$8*'Settings & Tariff'!$B$9),L18*H18*1000/('Settings & Tariff'!$B$8/SQRT(3)*'Settings & Tariff'!$B$9))) -> 11.784329 | O18: =IF(B18="","",K18*G18) -> 187.2 | P18: =IF(B18="","",IF($O$7=0,0,O18/$O$7*$P$7)) -> 59.122998
A19: 10 | B19: Forklift battery charger | C19: Motor / Machinery | D19: 6000 | E19: 1 | F19: 8 | G19: 26 | H19: 0.85 | I19: Y | J19: 3P | K19: =IF(B19="","",D19*E19*H19*F19/1000) -> 40.8 | L19: =IF(B19="","",D19*E19/1000) -> 6 | M19: =IF(B19="","",IF(UPPER(I19)="Y",L19*H19,0)) -> 5.1 | N19: =IF(B19="","",IF(J19="3P",L19*H19*1000/(SQRT(3)*'Settings & Tariff'!$B$8*'Settings & Tariff'!$B$9),L19*H19*1000/('Settings & Tariff'!$B$8/SQRT(3)*'Settings & Tariff'!$B$9))) -> 8.3472328 | O19: =IF(B19="","",K19*G19) -> 1060.8 | P19: =IF(B19="","",IF($O$7=0,0,O19/$O$7*$P$7)) -> 335.03032
A20: 11 | B20: Roller shutter motors | C20: Motor / Machinery | D20: 750 | E20: 2 | F20: 1 | G20: 26 | H20: 1 | I20: N | J20: 3P | K20: =IF(B20="","",D20*E20*H20*F20/1000) -> 1.5 | L20: =IF(B20="","",D20*E20/1000) -> 1.5 | M20: =IF(B20="","",IF(UPPER(I20)="Y",L20*H20,0)) -> 0 | N20: =IF(B20="","",IF(J20="3P",L20*H20*1000/(SQRT(3)*'Settings & Tariff'!$B$8*'Settings & Tariff'!$B$9),L20*H20*1000/('Settings & Tariff'!$B$8/SQRT(3)*'Settings & Tariff'!$B$9))) -> 2.4550685 | O20: =IF(B20="","",K20*G20) -> 39 | P20: =IF(B20="","",IF($O$7=0,0,O20/$O$7*$P$7)) -> 12.317291
A21: 12 | B21: CCTV, alarm, router | C21: Other | D21: 300 | E21: 1 | F21: 24 | G21: 30 | H21: 1 | I21: Y | J21: B | K21: =IF(B21="","",D21*E21*H21*F21/1000) -> 7.2 | L21: =IF(B21="","",D21*E21/1000) -> 0.3 | M21: =IF(B21="","",IF(UPPER(I21)="Y",L21*H21,0)) -> 0.3 | N21: =IF(B21="","",IF(J21="3P",L21*H21*1000/(SQRT(3)*'Settings & Tariff'!$B$8*'Settings & Tariff'!$B$9),L21*H21*1000/('Settings & Tariff'!$B$8/SQRT(3)*'Settings & Tariff'!$B$9))) -> 1.4730411 | O21: =IF(B21="","",K21*G21) -> 216 | P21: =IF(B21="","",IF($O$7=0,0,O21/$O$7*$P$7)) -> 68.218844 | Q21: 24-hour load
A22: 13 | B22: Water pump 1 hp | C22: Motor / Machinery | D22: 750 | E22: 1 | F22: 2 | G22: 30 | H22: 0.9 | I22: N | J22: R | K22: =IF(B22="","",D22*E22*H22*F22/1000) -> 1.35 | L22: =IF(B22="","",D22*E22/1000) -> 0.75 | M22: =IF(B22="","",IF(UPPER(I22)="Y",L22*H22,0)) -> 0 | N22: =IF(B22="","",IF(J22="3P",L22*H22*1000/(SQRT(3)*'Settings & Tariff'!$B$8*'Settings & Tariff'!$B$9),L22*H22*1000/('Settings & Tariff'!$B$8/SQRT(3)*'Settings & Tariff'!$B$9))) -> 3.3143424 | O22: =IF(B22="","",K22*G22) -> 40.5 | P22: =IF(B22="","",IF($O$7=0,0,O22/$O$7*$P$7)) -> 12.791033
A23: 14 | G23: =IF(B23="","",'Settings & Tariff'!$B$22) | H23: =IF(B23="","",1) | I23: =IF(B23="","","Y") | J23: =IF(B23="","","R") | K23: =IF(B23="","",D23*E23*H23*F23/1000) | L23: =IF(B23="","",D23*E23/1000) | M23: =IF(B23="","",IF(UPPER(I23)="Y",L23*H23,0)) | N23: =IF(B23="","",IF(J23="3P",L23*H23*1000/(SQRT(3)*'Settings & Tariff'!$B$8*'Settings & Tariff'!$B$9),L23*H23*1000/('Settings & Tariff'!$B$8/SQRT(3)*'Settings & Tariff'!$B$9))) | O23: =IF(B23="","",K23*G23) | P23: =IF(B23="","",IF($O$7=0,0,O23/$O$7*$P$7))
A24: 15 | G24: =IF(B24="","",'Settings & Tariff'!$B$22) | H24: =IF(B24="","",1) | I24: =IF(B24="","","Y") | J24: =IF(B24="","","R") | K24: =IF(B24="","",D24*E24*H24*F24/1000) | L24: =IF(B24="","",D24*E24/1000) | M24: =IF(B24="","",IF(UPPER(I24)="Y",L24*H24,0)) | N24: =IF(B24="","",IF(J24="3P",L24*H24*1000/(SQRT(3)*'Settings & Tariff'!$B$8*'Settings & Tariff'!$B$9),L24*H24*1000/('Settings & Tariff'!$B$8/SQRT(3)*'Settings & Tariff'!$B$9))) | O24: =IF(B24="","",K24*G24) | P24: =IF(B24="","",IF($O$7=0,0,O24/$O$7*$P$7))
A25: 16 | G25: =IF(B25="","",'Settings & Tariff'!$B$22) | H25: =IF(B25="","",1) | I25: =IF(B25="","","Y") | J25: =IF(B25="","","R") | K25: =IF(B25="","",D25*E25*H25*F25/1000) | L25: =IF(B25="","",D25*E25/1000) | M25: =IF(B25="","",IF(UPPER(I25)="Y",L25*H25,0)) | N25: =IF(B25="","",IF(J25="3P",L25*H25*1000/(SQRT(3)*'Settings & Tariff'!$B$8*'Settings & Tariff'!$B$9),L25*H25*1000/('Settings & Tariff'!$B$8/SQRT(3)*'Settings & Tariff'!$B$9))) | O25: =IF(B25="","",K25*G25) | P25: =IF(B25="","",IF($O$7=0,0,O25/$O$7*$P$7))
A26: 17 | G26: =IF(B26="","",'Settings & Tariff'!$B$22) | H26: =IF(B26="","",1) | I26: =IF(B26="","","Y") | J26: =IF(B26="","","R") | K26: =IF(B26="","",D26*E26*H26*F26/1000) | L26: =IF(B26="","",D26*E26/1000) | M26: =IF(B26="","",IF(UPPER(I26)="Y",L26*H26,0)) | N26: =IF(B26="","",IF(J26="3P",L26*H26*1000/(SQRT(3)*'Settings & Tariff'!$B$8*'Settings & Tariff'!$B$9),L26*H26*1000/('Settings & Tariff'!$B$8/SQRT(3)*'Settings & Tariff'!$B$9))) | O26: =IF(B26="","",K26*G26) | P26: =IF(B26="","",IF($O$7=0,0,O26/$O$7*$P$7))
A27: 18 | G27: =IF(B27="","",'Settings & Tariff'!$B$22) | H27: =IF(B27="","",1) | I27: =IF(B27="","","Y") | J27: =IF(B27="","","R") | K27: =IF(B27="","",D27*E27*H27*F27/1000) | L27: =IF(B27="","",D27*E27/1000) | M27: =IF(B27="","",IF(UPPER(I27)="Y",L27*H27,0)) | N27: =IF(B27="","",IF(J27="3P",L27*H27*1000/(SQRT(3)*'Settings & Tariff'!$B$8*'Settings & Tariff'!$B$9),L27*H27*1000/('Settings & Tariff'!$B$8/SQRT(3)*'Settings & Tariff'!$B$9))) | O27: =IF(B27="","",K27*G27) | P27: =IF(B27="","",IF($O$7=0,0,O27/$O$7*$P$7))
A28: 19 | G28: =IF(B28="","",'Settings & Tariff'!$B$22) | H28: =IF(B28="","",1) | I28: =IF(B28="","","Y") | J28: =IF(B28="","","R") | K28: =IF(B28="","",D28*E28*H28*F28/1000) | L28: =IF(B28="","",D28*E28/1000) | M28: =IF(B28="","",IF(UPPER(I28)="Y",L28*H28,0)) | N28: =IF(B28="","",IF(J28="3P",L28*H28*1000/(SQRT(3)*'Settings & Tariff'!$B$8*'Settings & Tariff'!$B$9),L28*H28*1000/('Settings & Tariff'!$B$8/SQRT(3)*'Settings & Tariff'!$B$9))) | O28: =IF(B28="","",K28*G28) | P28: =IF(B28="","",IF($O$7=0,0,O28/$O$7*$P$7))
A29: 20 | G29: =IF(B29="","",'Settings & Tariff'!$B$22) | H29: =IF(B29="","",1) | I29: =IF(B29="","","Y") | J29: =IF(B29="","","R") | K29: =IF(B29="","",D29*E29*H29*F29/1000) | L29: =IF(B29="","",D29*E29/1000) | M29: =IF(B29="","",IF(UPPER(I29)="Y",L29*H29,0)) | N29: =IF(B29="","",IF(J29="3P",L29*H29*1000/(SQRT(3)*'Settings & Tariff'!$B$8*'Settings & Tariff'!$B$9),L29*H29*1000/('Settings & Tariff'!$B$8/SQRT(3)*'Settings & Tariff'!$B$9))) | O29: =IF(B29="","",K29*G29) | P29: =IF(B29="","",IF($O$7=0,0,O29/$O$7*$P$7))
A30: 21 | G30: =IF(B30="","",'Settings & Tariff'!$B$22) | H30: =IF(B30="","",1) | I30: =IF(B30="","","Y") | J30: =IF(B30="","","R") | K30: =IF(B30="","",D30*E30*H30*F30/1000) | L30: =IF(B30="","",D30*E30/1000) | M30: =IF(B30="","",IF(UPPER(I30)="Y",L30*H30,0)) | N30: =IF(B30="","",IF(J30="3P",L30*H30*1000/(SQRT(3)*'Settings & Tariff'!$B$8*'Settings & Tariff'!$B$9),L30*H30*1000/('Settings & Tariff'!$B$8/SQRT(3)*'Settings & Tariff'!$B$9))) | O30: =IF(B30="","",K30*G30) | P30: =IF(B30="","",IF($O$7=0,0,O30/$O$7*$P$7))
A31: 22 | G31: =IF(B31="","",'Settings & Tariff'!$B$22) | H31: =IF(B31="","",1) | I31: =IF(B31="","","Y") | J31: =IF(B31="","","R") | K31: =IF(B31="","",D31*E31*H31*F31/1000) | L31: =IF(B31="","",D31*E31/1000) | M31: =IF(B31="","",IF(UPPER(I31)="Y",L31*H31,0)) | N31: =IF(B31="","",IF(J31="3P",L31*H31*1000/(SQRT(3)*'Settings & Tariff'!$B$8*'Settings & Tariff'!$B$9),L31*H31*1000/('Settings & Tariff'!$B$8/SQRT(3)*'Settings & Tariff'!$B$9))) | O31: =IF(B31="","",K31*G31) | P31: =IF(B31="","",IF($O$7=0,0,O31/$O$7*$P$7))
A32: 23 | G32: =IF(B32="","",'Settings & Tariff'!$B$22) | H32: =IF(B32="","",1) | I32: =IF(B32="","","Y") | J32: =IF(B32="","","R") | K32: =IF(B32="","",D32*E32*H32*F32/1000) | L32: =IF(B32="","",D32*E32/1000) | M32: =IF(B32="","",IF(UPPER(I32)="Y",L32*H32,0)) | N32: =IF(B32="","",IF(J32="3P",L32*H32*1000/(SQRT(3)*'Settings & Tariff'!$B$8*'Settings & Tariff'!$B$9),L32*H32*1000/('Settings & Tariff'!$B$8/SQRT(3)*'Settings & Tariff'!$B$9))) | O32: =IF(B32="","",K32*G32) | P32: =IF(B32="","",IF($O$7=0,0,O32/$O$7*$P$7))
A33: 24 | G33: =IF(B33="","",'Settings & Tariff'!$B$22) | H33: =IF(B33="","",1) | I33: =IF(B33="","","Y") | J33: =IF(B33="","","R") | K33: =IF(B33="","",D33*E33*H33*F33/1000) | L33: =IF(B33="","",D33*E33/1000) | M33: =IF(B33="","",IF(UPPER(I33)="Y",L33*H33,0)) | N33: =IF(B33="","",IF(J33="3P",L33*H33*1000/(SQRT(3)*'Settings & Tariff'!$B$8*'Settings & Tariff'!$B$9),L33*H33*1000/('Settings & Tariff'!$B$8/SQRT(3)*'Settings & Tariff'!$B$9))) | O33: =IF(B33="","",K33*G33) | P33: =IF(B33="","",IF($O$7=0,0,O33/$O$7*$P$7))
A34: 25 | G34: =IF(B34="","",'Settings & Tariff'!$B$22) | H34: =IF(B34="","",1) | I34: =IF(B34="","","Y") | J34: =IF(B34="","","R") | K34: =IF(B34="","",D34*E34*H34*F34/1000) | L34: =IF(B34="","",D34*E34/1000) | M34: =IF(B34="","",IF(UPPER(I34)="Y",L34*H34,0)) | N34: =IF(B34="","",IF(J34="3P",L34*H34*1000/(SQRT(3)*'Settings & Tariff'!$B$8*'Settings & Tariff'!$B$9),L34*H34*1000/('Settings & Tariff'!$B$8/SQRT(3)*'Settings & Tariff'!$B$9))) | O34: =IF(B34="","",K34*G34) | P34: =IF(B34="","",IF($O$7=0,0,O34/$O$7*$P$7))
... A39: 30 | G39: =IF(B39="","",'Settings & Tariff'!$B$22) | H39: =IF(B39="","",1) | I39: =IF(B39="","","Y") | J39: =IF(B39="","","R") | K39: =IF(B39="","",D39*E39*H39*F39/1000) | L39: =IF(B39="","",D39*E39/1000) | M39: =IF(B39="","",IF(UPPER(I39)="Y",L39*H39,0)) | N39: =IF(B39="","",IF(J39="3P",L39*H39*1000/(SQRT(3)*'Settings & Tariff'!$B$8*'Settings & Tariff'!$B$9),L39*H39*1000/('Settings & Tariff'!$B$8/SQRT(3)*'Settings & Tariff'!$B$9))) | O39: =IF(B39="","",K39*G39) | P39: =IF(B39="","",IF($O$7=0,0,O39/$O$7*$P$7))
B40: TOTAL | K40: =SUM(K10:K39) -> 180.46 | L40: =SUM(L10:L39) -> 29.39 | M40: =SUM(M10:M39) -> 19.82 | O40: =SUM(O10:O39) -> 4793.84 | P40: =SUM(P10:P39) -> 1514.0288
B42: SUMMARY BY TYPE
B43: Type | C43: Items | E43: Connected kW | G43: Demand kW | I43: Monthly kWh | K43: % of kWh | L43: Monthly cost (RM)
B44: Spotlight | C44: =COUNTIF(C10:C39,B44) -> 1 | E44: =SUMIF(C10:C39,B44,L10:L39) -> 0.5 | G44: =SUMIF(C10:C39,B44,M10:M39) -> 0.5 | I44: =SUMIF(C10:C39,B44,O10:O39) -> 180 | K44: =IF($O$7=0,0,I44/$O$7) -> 0.037548187 | L44: =SUMIF(C10:C39,B44,P10:P39) -> 56.849036
B45: Lighting | C45: =COUNTIF(C10:C39,B45) -> 2 | E45: =SUMIF(C10:C39,B45,L10:L39) -> 6.54 | G45: =SUMIF(C10:C39,B45,M10:M39) -> 6.54 | I45: =SUMIF(C10:C39,B45,O10:O39) -> 1686.36 | K45: =IF($O$7=0,0,I45/$O$7) -> 0.35177645 | L45: =SUMIF(C10:C39,B45,P10:P39) -> 532.59967
B46: Air-cond | C46: =COUNTIF(C10:C39,B46) -> 3 | E46: =SUMIF(C10:C39,B46,L10:L39) -> 5.4 | G46: =SUMIF(C10:C39,B46,M10:M39) -> 3.78 | I46: =SUMIF(C10:C39,B46,O10:O39) -> 999.18 | K46: =IF($O$7=0,0,I46/$O$7) -> 0.20842999 | L46: =SUMIF(C10:C39,B46,P10:P39) -> 315.569
B47: 13A Socket | C47: =COUNTIF(C10:C39,B47) -> 3 | E47: =SUMIF(C10:C39,B47,L10:L39) -> 8.4 | G47: =SUMIF(C10:C39,B47,M10:M39) -> 3.6 | I47: =SUMIF(C10:C39,B47,O10:O39) -> 572 | K47: =IF($O$7=0,0,I47/$O$7) -> 0.11931979 | L47: =SUMIF(C10:C39,B47,P10:P39) -> 180.6536
...

Sheet Settings & Tariff
A1: WAREHOUSE ELECTRICAL LOAD CALCULATOR - SETTINGS
A2: Yellow cells are inputs. Everything else calculates automatically.
A4: 1. INCOMING SUPPLY
A5: Site name | B5: Holy Builders Warehouse, Bintulu
A6: Number of phases (1 or 3) | B6: 3 | D6: 3-phase incoming
A7: Main incoming breaker rating | B7: 60 | C7: A | D7: As given: 60 A
A8: Line voltage | B8: 415 | C8: V | D8: 415 V line-line for 3-phase; 240 V for single phase
A9: Power factor | B9: 0.85 | D9: Typical mixed load 0.85; aircond/motors ~0.8
A10: Diversity factor on peak loads | B10: 0.8 | D10: Not everything ticked "Peak" runs at full load together
A11: Safe continuous loading of breaker | B11: 0.8 | C11: % | D11: Good practice: keep continuous load ≤ 80% of breaker rating
A12: Supply capacity (kVA) | B12: =IF('Settings & Tariff'!$B$6=3,SQRT(3)*'Settings & Tariff'!$B$8*'Settings & Tariff'!$B$7/1000,'Settings & Tariff'!$B$8*'Settings & Tariff'!$B$7/1000) -> 43.128065
A13: Usable power at power factor (kW) | B13: ='Settings & Tariff'!$B$12*'Settings & Tariff'!$B$9 -> 36.658855
A14: Safe continuous current per phase (A) | B14: ='Settings & Tariff'!$B$7*'Settings & Tariff'!$B$11 -> 48
A16: 2. TARIFF (Sarawak Energy)
A17: Tariff: type C1 or C2 | B17: C1 | D17: C1 = commercial block rates (no demand meter, usual for 60 A). C2 = 24.5 sen/kWh + RM 16/kW max demand
A18: C2 energy rate | B18: 24.5 | C18: sen/kWh
A19: C2 maximum demand charge | B19: 16 | C19: RM/kW
A20: C1 minimum monthly charge | B20: 10 | C20: RM
A21: Taxes / levies on bill | B21: 0 | C21: % | D21: Usually 0 for commercial in Sarawak
A22: Default operating days per month | B22: 26 | C22: days
A23: Grid carbon factor | B23: 0.34 | C23: kg CO₂/kWh | D23: Sarawak grid (mostly hydro) - approx.
A25: 3. C1 BLOCK RATES (editable - verify against your latest bill)
A26: Block | B26: From kWh (excl.) | C26: To kWh (incl.) | D26: sen/kWh | E26: kWh in block | F26: Charge (RM)
A27: 1 | B27: 0 | C27: 100 | D27: 20 | E27: =MAX(0,MIN('Load Schedule'!$O$7,C27)-B27) -> 100 | F27: =E27*D27/100 -> 20
A28: 2 | B28: =C27 -> 100 | C28: 200 | D28: 24 | E28: =MAX(0,MIN('Load Schedule'!$O$7,C28)-B28) -> 100 | F28: =E28*D28/100 -> 24
A29: 3 | B29: =C28 -> 200 | C29: 10000 | D29: 32 | E29: =MAX(0,MIN('Load Schedule'!$O$7,C29)-B29) -> 4593.84 | F29: =E29*D29/100 -> 1470.0288
A30: 4 | B30: =C29 -> 10000 | C30: 20000 | D30: 31 | E30: =MAX(0,MIN('Load Schedule'!$O$7,C30)-B30) -> 0 | F30: =E30*D30/100 -> 0
A31: 5 | B31: =C30 -> 20000 | C31: 99999999 | D31: 30 | E31: =MAX(0,MIN('Load Schedule'!$O$7,C31)-B31) -> 0 | F31: =E31*D31/100 -> 0
E32: C1 energy charge | F32: =SUM(F27:F31) -> 1514.0288
A34: 4. TYPICAL RATINGS (reference for the Watts column)
A35: Equipment | B35: Typical W each | C35: Note
A36: LED spotlight / floodlight | B36: 50 | C36: 30-100 W LED; halogen flood 500 W
A37: LED high-bay light | B37: 150 | C37: 100-200 W
A38: LED tube 4 ft | B38: 18 | C38: T8 LED
A39: Fluorescent 2 x 36 W fitting | B39: 90 | C39: incl. ballast
A40: Air-cond 1.0 hp | B40: 900 | C40: ~0.9 kW running
A41: Air-cond 1.5 hp | B41: 1300
A42: Air-cond 2.0 hp | B42: 1800
A43: Air-cond 2.5 hp | B43: 2300
A44: Air-cond cassette 3.0 hp | B44: 2800
...
