Workbook

Sheet Material Requirement
A1: HOLY BUILDERS SDN. BHD.
A2: MATERIAL REQUIREMENT SCHEDULE - WATERPROOFING WORKS
A4: Project | B4: The Proposed Provision and Laying of Waterproofing Membrane to Existing Roof Balconies and Associated Works at Wisma Bintulu Building
A5: Client | B5: Lembaga Kemajuan Bintulu (BDA)
A6: Drawing ref. | B6: BDA-MWS/BLD/1/2025 (1/11 - 11/11)
A7: Doc. no. | B7: HB/MR/WB-WP/2026-001 Rev. 0
A8: Date | B8: October 2026
A9: Prepared by
A10: Checked by
A12: Wastage / top-up allowance | B12: 0.18 | C12: <- editable; applied to every line
A14: A. MEASURED AREAS (from CAD take-off)
A15: Ref | B15: Element | C15: Floor | D15: Area (m²) | E15: Source
A16: A1 | B16: Existing RC gutter | C16: 1st Floor | D16: 309.84 | E16: Waterproofing_Contract.dwg hatch take-off (plan area)
A17: A2 | B17: Scupper drains | C17: 3rd - 6th Floor | D17: 337.9 | E17: Waterproofing_Contract.dwg hatch take-off (plan area)
A18: A3 | B18: Balcony floors | C18: 3rd - 6th Floor | D18: 2688.1 | E18: Waterproofing_Contract.dwg hatch take-off (plan area)
A20: B. MATERIAL REQUIREMENT
A21: Item | B21: Material / product | C21: Specification / description | D21: Used for | E21: Area ref | F21: Area (m²) | G21: Coats | H21: Consumption (kg/m² per coat) | I21: Net qty (kg) | J21: Wastage % | K21: Required qty (kg) | L21: Unit pack | M21: Pack size (kg) | N21: Packs to order | O21: Supplier | P21: Remarks
A22: 1 | B22: SikaTop Seal-107 (MY) | C22: 2-part polymer-modified cementitious waterproofing slurry; Part A liquid 5 kg + Part B powder 20 kg | D22: Existing RC gutter - 3 coats | E22: A1 | F22: =$D$16 -> 309.84 | G22: 3 | H22: 1.5 | I22: =F22*G22*H22 -> 1394.28 | J22: =$B$12 -> 0.18 | K22: =I22*(1+J22) -> 1645.2504 | L22: 25 kg set | M22: 25 | N22: =ROUNDUP(K22/M22,0) -> 66 | O22: Sika Kimia Sdn Bhd | P22: 1.5 kg/m²/coat per Sika PDS (terraces/balconies, up to 1 m head). Order items 1 & 2 as one lot.
A23: 2 | B23: SikaTop Seal-107 (MY) | C23: As item 1 | D23: Scupper drains - 3 coats | E23: A2 | F23: =$D$17 -> 337.9 | G23: 3 | H23: 1.5 | I23: =F23*G23*H23 -> 1520.55 | J23: =$B$12 -> 0.18 | K23: =I23*(1+J23) -> 1794.249 | L23: 25 kg set | M23: 25 | N23: =ROUNDUP(K23/M23,0) -> 72 | O23: Sika Kimia Sdn Bhd | P23: As item 1.
A24: 3 | B24: Sikalastic U-Primer | C24: 1-part solvent-based polyurethane primer for concrete / cementitious substrates | D24: Balcony floors - 1 coat before Sikalastic-632 R | E24: A3 | F24: =$D$18 -> 2688.1 | G24: 1 | H24: 0.2 | I24: =F24*G24*H24 -> 537.62 | J24: =$B$12 -> 0.18 | K24: =I24*(1+J24) -> 634.3916 | L24: 14 kg pail | M24: 14 | N24: =ROUNDUP(K24/M24,0) -> 46 | O24: Sika Kimia Sdn Bhd | P24: ~0.20 kg/m² per coat (Sika Malaysia PDS Apr 2023).
A25: 4 | B25: Sikalastic-632 R | C25: 1-part moisture-triggered rapid-curing PU liquid-applied roof waterproofing membrane, grey, density ~1.40 kg/l | D25: Balcony floors - 3 layers | E25: A3 | F25: =$D$18 -> 2688.1 | G25: 3 | H25: 0.7 | I25: =F25*G25*H25 -> 5645.01 | J25: =$B$12 -> 0.18 | K25: =I25*(1+J25) -> 6661.1118 | L25: 21 kg pail | M25: 21 | N25: =ROUNDUP(K25/M25,0) -> 318 | O25: Sika Kimia Sdn Bhd | P25: 0.70 kg/m²/coat x 3 = 2.10 kg/m² (upper value of PDS range 1.05-2.10 kg/m²).
A26: 5 | B26: Sika Reemat Premium | C26: Glass-fibre reinforcement mat for Sikalastic liquid membranes (roll) | D26: Local reinforcement: 300 mm strips at scupper drain edges, RWDP outlets, upstands, cracks | E26: - | F26: - | G26: - | H26: - | I26: 600 | J26: =$B$12 -> 0.18 | K26: =I26*(1+J26) -> 708 | L26: roll (1 m x 50 m = 50 m²) | M26: 50 | N26: =ROUNDUP(K26/M26,0) -> 15 | O26: Sika Kimia Sdn Bhd | P26: Allowance in m² (not kg): 300 mm strips both sides of all scupper drain rings, approx. 2 x 0.30 m x 1,000 m = 600 m². Roll 50 m² - confirm with Sika.
A27: 6 | B27: Sika Reactivation Primer | C27: Primer for overcoating cured Sikalastic-632 R after > 2 days | D27: Contingency for interrupted coats / day joints | E27: - | F27: - | G27: - | H27: - | I27: 20 | J27: =$B$12 -> 0.18 | K27: =I27*(1+J27) -> 23.6 | L27: pail | M27: 5 | N27: =ROUNDUP(K27/M27,0) -> 5 | O27: Sika Kimia Sdn Bhd | P27: Allowance - adjust to programme.
A28: 7 | B28: Sikaflex PU sealant (Sikaflex-11 FC+ or equivalent) | C28: 1-part polyurethane elastic joint sealant | D28: Sealing of new 100/110 mm uPVC RWDP penetrations, cracks > 0.3 mm, upstand joints | E28: - | F28: - | G28: - | H28: - | I28: 40 | J28: =$B$12 -> 0.18 | K28: =I28*(1+J28) -> 47.2 | L28: cartridge (300 ml) | M28: 0.4 | N28: =ROUNDUP(K28/M28,0) -> 118 | O28: Sika Kimia Sdn Bhd | P28: Allowance: approx. 1 cartridge per RWDP penetration + crack sealing. Enter required kg (0.4 kg per 300 ml cartridge).
A29: 8 | B29: Sika repair mortar (SikaTop-122 / Sika MonoTop) | C29: Polymer-modified cementitious repair / fairing mortar | D29: Repair of spalls, honeycombs, re-forming scupper drain profile and falls | E29: - | F29: - | G29: - | H29: - | I29: 500 | J29: =$B$12 -> 0.18 | K29: =I29*(1+J29) -> 590 | L29: 25 kg bag | M29: 25 | N29: =ROUNDUP(K29/M29,0) -> 24 | O29: Sika Kimia Sdn Bhd | P29: Allowance - to be confirmed after joint defect survey.
A30: 9 | B30: Sika Thinner C / Colma Cleaner | C30: Solvent for tool cleaning (Sikalastic products) | D30: Cleaning of rollers, brushes and spills | E30: - | F30: - | G30: - | H30: - | I30: 40 | J30: =$B$12 -> 0.18 | K30: =I30*(1+J30) -> 47.2 | L30: 5 L tin | M30: 4 | N30: =ROUNDUP(K30/M30,0) -> 12 | O30: Sika Kimia Sdn Bhd | P30: Allowance.
A31: 10 | B31: uPVC pipe 100 / 110 mm dia. (Class D) with fittings and sleeves | C31: New RWDP coring through slab / gutter wall | D31: Associated drainage works per drawings 2/11 - 7/11 | E31: - | F31: - | G31: - | H31: - | I31: - | J31: - | K31: - | L31: length (5.8 m) | M31: - | N31: 12 | O31: Local supplier | P31: Quantity by count of RWDP coring points on drawings - enter number of lengths in col N.
A32: 11 | B32: Floor trap covers (approved type) | C32: Replacement covers for existing floor traps | D32: 3rd - 6th floor scupper drain outlets | E32: - | F32: - | G32: - | H32: - | I32: - | J32: - | K32: - | L32: no. | M32: - | N32: 16 | O32: Local supplier | P32: Enter number required in col N after site count.
A33: 12 | B33: Non-shrink grout | C33: Cementitious non-shrink grout for RWDP core-hole annulus | D33: RWDP coring | E33: - | F33: - | G33: - | H33: - | I33: 100 | J33: =$B$12 -> 0.18 | K33: =I33*(1+J33) -> 118 | L33: 25 kg bag | M33: 25 | N33: =ROUNDUP(K33/M33,0) -> 5 | O33: Sika / local | P33: Allowance.
A35: C. ORDER SUMMARY - SIKA PRODUCTS
B36: Product | I36: Net qty (kg) | K36: Required qty (kg) | L36: Unit pack | M36: Pack size (kg) | N36: Packs to order
B37: SikaTop Seal-107 (MY) | I37: =I22+I23 -> 2914.83 | K37: =K22+K23 -> 3439.4994 | L37: 25 kg set | M37: =M22 -> 25 | N37: =ROUNDUP(K37/M37,0) -> 138
B38: Sikalastic U-Primer | I38: =I24 -> 537.62 | K38: =K24 -> 634.3916 | L38: 14 kg pail | M38: =M24 -> 14 | N38: =ROUNDUP(K38/M38,0) -> 46
B39: Sikalastic-632 R | I39: =I25 -> 5645.01 | K39: =K25 -> 6661.1118 | L39: 21 kg pail | M39: =M25 -> 21 | N39: =ROUNDUP(K39/M39,0) -> 318
B40: Sika Reemat Premium (m²) | I40: =I26 -> 600 | K40: =K26 -> 708 | L40: roll 50 m² | M40: =M26 -> 50 | N40: =ROUNDUP(K40/M40,0) -> 15
B41: Sika Reactivation Primer | I41: =I27 -> 20 | K41: =K27 -> 23.6 | L41: pail | M41: =M27 -> 5 | N41: =ROUNDUP(K41/M41,0) -> 5
B42: Sikaflex PU sealant | I42: =I28 -> 40 | K42: =K28 -> 47.2 | L42: cartridge | M42: =M28 -> 0.4 | N42: =ROUNDUP(K42/M42,0) -> 118
B43: Sika repair mortar | I43: =I29 -> 500 | K43: =K29 -> 590 | L43: 25 kg bag | M43: =M29 -> 25 | N43: =ROUNDUP(K43/M43,0) -> 24
A45: Notes:
A46: 1. Yellow cells are inputs (areas, coats, consumption rates, pack sizes, allowances, wastage %). All other figures are formulas.
...

Sheet Per-floor breakdown
A1: MATERIAL REQUIREMENT BY FLOOR (for phased delivery)
A2: Quantities include the wastage % set on the 'Material Requirement' sheet. Consumption rates and pack sizes are linked from that sheet.
A4: Floor | B4: Floor area (m²) | C4: Gutter / drain area (m²) | D4: Sikalastic U-Primer (kg) | E4: Sikalastic-632 R (kg) | F4: SikaTop Seal-107 (kg) | G4: U-Primer pails (14 kg) | H4: 632 R pails (21 kg) | I4: Seal-107 sets (25 kg)
A5: 1st Floor | B5: 0 | C5: 309.84 | D5: =B5*'Material Requirement'!$G$24*'Material Requirement'!$H$24*(1+'Material Requirement'!$B$12) -> 0 | E5: =B5*'Material Requirement'!$G$25*'Material Requirement'!$H$25*(1+'Material Requirement'!$B$12) -> 0 | F5: =C5*'Material Requirement'!$G$22*'Material Requirement'!$H$22*(1+'Material Requirement'!$B$12) -> 1645.2504 | G5: =ROUNDUP(D5/'Material Requirement'!$M$24,0) -> 0 | H5: =ROUNDUP(E5/'Material Requirement'!$M$25,0) -> 0 | I5: =ROUNDUP(F5/'Material Requirement'!$M$22,0) -> 66
A6: 3rd Floor | B6: 960.85 | C6: 110.49 | D6: =B6*'Material Requirement'!$G$24*'Material Requirement'!$H$24*(1+'Material Requirement'!$B$12) -> 226.7606 | E6: =B6*'Material Requirement'!$G$25*'Material Requirement'!$H$25*(1+'Material Requirement'!$B$12) -> 2380.9863 | F6: =C6*'Material Requirement'!$G$22*'Material Requirement'!$H$22*(1+'Material Requirement'!$B$12) -> 586.7019 | G6: =ROUNDUP(D6/'Material Requirement'!$M$24,0) -> 17 | H6: =ROUNDUP(E6/'Material Requirement'!$M$25,0) -> 114 | I6: =ROUNDUP(F6/'Material Requirement'!$M$22,0) -> 24
A7: 4th Floor | B7: 793.02 | C7: 96.79 | D7: =B7*'Material Requirement'!$G$24*'Material Requirement'!$H$24*(1+'Material Requirement'!$B$12) -> 187.15272 | E7: =B7*'Material Requirement'!$G$25*'Material Requirement'!$H$25*(1+'Material Requirement'!$B$12) -> 1965.1036 | F7: =C7*'Material Requirement'!$G$22*'Material Requirement'!$H$22*(1+'Material Requirement'!$B$12) -> 513.9549 | G7: =ROUNDUP(D7/'Material Requirement'!$M$24,0) -> 14 | H7: =ROUNDUP(E7/'Material Requirement'!$M$25,0) -> 94 | I7: =ROUNDUP(F7/'Material Requirement'!$M$22,0) -> 21
A8: 5th Floor | B8: 553.47 | C8: 72.02 | D8: =B8*'Material Requirement'!$G$24*'Material Requirement'!$H$24*(1+'Material Requirement'!$B$12) -> 130.61892 | E8: =B8*'Material Requirement'!$G$25*'Material Requirement'!$H$25*(1+'Material Requirement'!$B$12) -> 1371.4987 | F8: =C8*'Material Requirement'!$G$22*'Material Requirement'!$H$22*(1+'Material Requirement'!$B$12) -> 382.4262 | G8: =ROUNDUP(D8/'Material Requirement'!$M$24,0) -> 10 | H8: =ROUNDUP(E8/'Material Requirement'!$M$25,0) -> 66 | I8: =ROUNDUP(F8/'Material Requirement'!$M$22,0) -> 16
A9: 6th Floor | B9: 380.76 | C9: 58.6 | D9: =B9*'Material Requirement'!$G$24*'Material Requirement'!$H$24*(1+'Material Requirement'!$B$12) -> 89.85936 | E9: =B9*'Material Requirement'!$G$25*'Material Requirement'!$H$25*(1+'Material Requirement'!$B$12) -> 943.52328 | F9: =C9*'Material Requirement'!$G$22*'Material Requirement'!$H$22*(1+'Material Requirement'!$B$12) -> 311.166 | G9: =ROUNDUP(D9/'Material Requirement'!$M$24,0) -> 7 | H9: =ROUNDUP(E9/'Material Requirement'!$M$25,0) -> 45 | I9: =ROUNDUP(F9/'Material Requirement'!$M$22,0) -> 13
A10: TOTAL | B10: =SUM(B5:B9) -> 2688.1 | C10: =SUM(C5:C9) -> 647.74 | D10: =SUM(D5:D9) -> 634.3916 | E10: =SUM(E5:E9) -> 6661.1118 | F10: =SUM(F5:F9) -> 3439.4994 | G10: =SUM(G5:G9) -> 48 | H10: =SUM(H5:H9) -> 319 | I10: =SUM(I5:I9) -> 140
A12: Note: per-floor pack counts are rounded up individually, so their sum may exceed the single-lot order quantity on the Material Requirement sheet by a few packs.
