Workbook

Sheet Summary
A1: WTP 20 m3/h x 6 h/day - Power Supply and Pump Sizing Summary
A2: Shelter 18.3 m x 7.2 m x 3.6 m. 415 V 3-phase 50 Hz. All figures link to the calculation sheets.
A4: Item | B4: Value | C4: Unit | D4: Note
A5: PUMP MOTORS
A6: Raw Water Pump (duty + standby) - calculated motor | B6: ='Pump Sizing'!K5 -> 2.2 | C6: kW | D6: 10 m3/h at 30 m
A7: Raw Water Pump - drawing motor | B7: ='Pump Sizing'!L5 -> 5.5 | C7: kW
A8: Backwash Pump (duty + standby) - calculated motor | B8: ='Pump Sizing'!K7 -> 5.5 | C8: kW | D8: 30 m3/h at 30 m
A9: Backwash Pump - drawing motor | B9: ='Pump Sizing'!L7 -> 5.5 | C9: kW
A10: Treated Water Pump - calculated motor | B10: ='Pump Sizing'!K9 -> 2.2 | C10: kW | D10: 12 m3/h at 30 m
A11: Treated Water Pump - drawing motor | B11: ='Pump Sizing'!L9 -> 5.5 | C11: kW
A12: Total installed pump motor kW (design basis) | B12: ='Pump Sizing'!M11 -> 27.5 | C12: kW | D12: 5 motors
A13: Motor FLC each (design basis, 415 V) | B13: ='Pump Sizing'!P5 -> 10.046783 | C13: A
A14: Motor feeder MCCB (each) | B14: ='Load Schedule'!Q5 -> 25 | C14: A | D14: 3P, with Star-Delta starter
A15: Motor feeder cable (each) | B15: ='Load Schedule'!V5 -> 2.5 | C15: mm2 | D15: Cu XLPE/SWA/PVC 4-core
A16: INCOMING SUPPLY
A17: Total connected load | B17: ='Incoming Supply'!B6 -> 33.96 | C17: kW
A18: Maximum demand | B18: ='Incoming Supply'!B8 -> 27.905112 | C18: kVA | D18: Standby pumps excluded
A19: Maximum demand current | B19: ='Incoming Supply'!B10 -> 38.821744 | C19: A
A20: Design current incl. spare | B20: ='Incoming Supply'!B13 -> 48.527181 | C20: A
A21: Recommended main MCCB | B21: ='Incoming Supply'!B21 -> 63 | C21: A | D21: 4-pole
A22: Main MCCB on drawing | B22: ='Incoming Supply'!B19 -> 225 | C22: A | D22: 4P 225 A
A23: Incoming cable | B23: ='Incoming Supply'!B26 -> 16 | C23: mm2 | D23: Cu XLPE/SWA/PVC 4-core
A24: Declared maximum demand for TNB | B24: ='Incoming Supply'!B33 -> 35 | C24: kVA
A25: Standby generator (if required) | B25: ='Incoming Supply'!B43 -> 40 | C25: kVA
A26: Estimated energy | B26: ='Incoming Supply'!B36 -> 4302.4821 | C26: kWh/month | D26: Upper bound

Sheet Inputs
A1: Water Treatment Plant 20 m3/h - Electrical Design Inputs
A2: Blue text = input (edit here). Black = formula. Yellow fill = assumption to be confirmed by the user/vendor.
A4: Parameter | B4: Value | C4: Unit | D4: Basis / Source | F4: Std IEC motor kW | H4: Std MCCB/MCB (A) | J4: Cable size (mm2) | K4: Ampacity (A) Cu XLPE/SWA/PVC 4-core, on tray, 30 C | L4: Volt drop (mV/A/m)
A5: SYSTEM PARAMETERS | F5: 0.37 | H5: 6 | J5: 1.5 | K5: 22 | L5: 29
A6: Supply voltage, line-to-line | B6: 415 | C6: V | D6: TNB LV 3-phase 4-wire supply, per drawing 'Main Incoming 415V, 3PH, 50Hz' | F6: 0.55 | H6: 10 | J6: 2.5 | K6: 30 | L6: 18
A7: Frequency | B7: 50 | C7: Hz | D7: Per drawing | F7: 0.75 | H7: 16 | J7: 4 | K7: 40 | L7: 11
A8: Single-phase voltage, line-to-neutral | B8: =ROUND(B6/SQRT(3),0) -> 240 | C8: V | D8: Derived from line voltage | F8: 1.1 | H8: 20 | J8: 6 | K8: 52 | L8: 7.3
A9: Motor power factor at full load | B9: 0.85 | C9: - | D9: Typical IE3 4-pole 5.5 kW motor at full load. Confirm from motor nameplate. | F9: 1.5 | H9: 25 | J9: 10 | K9: 71 | L9: 4.4
A10: Lighting / small-power power factor | B10: 0.9 | C10: - | D10: Assumed. LED lighting and general sockets. | F10: 2.2 | H10: 32 | J10: 16 | K10: 94 | L10: 2.8
A11: Motor efficiency (IE3, 4-pole, 5.5 kW class) | B11: 0.896 | C11: - | D11: IEC 60034-30-1 IE3 minimum, 4-pole, 5.5 kW = 89.6% | F11: 3 | H11: 40 | J11: 25 | K11: 124 | L11: 1.75
A12: Pump hydraulic efficiency at duty point | B12: 0.65 | C12: - | D12: Assumed for end-suction centrifugal pumps of this size. Replace with value from vendor pump curve. | F12: 4 | H12: 50 | J12: 35 | K12: 153 | L12: 1.25
A13: Motor sizing margin on shaft power | B13: 1.2 | C13: - | D13: Shaft power x 1.20 before selecting next standard IEC motor (common practice for pumps < 7.5 kW) | F13: 5.5 | H13: 63 | J13: 50 | K13: 185 | L13: 0.93
A14: Water density | B14: 1000 | C14: kg/m3 | D14: Fresh water at 25 C | F14: 7.5 | H14: 80 | J14: 70 | K14: 236 | L14: 0.63
A15: Gravitational acceleration | B15: 9.81 | C15: m/s2 | F15: 11 | H15: 100 | J15: 95 | K15: 288 | L15: 0.46
A16: PROTECTION AND CABLE SIZING | F16: 15 | H16: 125 | J16: 120 | K16: 335 | L16: 0.38
A17: Breaker sizing factor - motor feeders (x FLC) | B17: 2 | C17: - | D17: MCCB magnetic/thermal rating for motor circuits; overload protection is by the starter overload relay. Gives 25 A for a 5.5 kW motor, matching drawing. | F17: 18.5 | H17: 160 | J17: 150 | K17: 385 | L17: 0.31
A18: Breaker sizing factor - non-motor feeders (x FLC) | B18: 1.25 | C18: - | D18: Standard 125% of design current | F18: 22 | H18: 200 | J18: 185 | K18: 440 | L18: 0.25
A19: Cable derating factor (grouping x ambient) | B19: 0.87 | C19: - | D19: Assumed 35 C ambient, up to 3 circuits grouped on tray. Confirm against installation method. | F19: 30 | H19: 225 | J19: 240 | K19: 515 | L19: 0.19
A20: Max voltage drop - motor and sub-main feeders | B20: 0.04 | C20: % | D20: 4% of nominal (MS IEC 60364 / BS 7671 guidance for power) | H20: 250
A21: Max voltage drop - lighting / small power | B21: 0.03 | C21: % | D21: 3% of nominal | H21: 320 | J21: Cable ratings are indicative values for copper XLPE-insulated SWA/PVC 4-core cables on perforated tray (BS 7671 Table 4E4A order of magnitude). Verify against the cable manufacturer's catalogue before purchase.
A22: Diversity factor - lighting and small power | B22: 0.8 | C22: - | D22: Assumed | H22: 400
A23: Spare capacity on incoming supply | B23: 0.25 | C23: - | D23: 25% allowance for future loads when selecting main MCCB and incoming cable
A24: DOL starting current multiple (x FLC) | B24: 6 | C24: - | D24: Typical squirrel-cage motor
A25: Star-Delta starting current multiple (x FLC) | B25: 2 | C25: - | D25: Approx. one-third of DOL starting current
A26: Star-Delta threshold (motors at or above this use Star-Delta) | B26: 4 | C26: kW | D26: Per drawing: Star-Delta recommended for 5.5 kW pumps
A27: Electrical design basis for motor kW (Drawing / Calculated) | B27: Drawing | C27: - | D27: 'Drawing' sizes feeders on the 5.5 kW motors shown. 'Calculated' uses the hydraulic calculation result on the Pump Sizing sheet.
A28: OPERATING PROFILE
A29: Plant running hours per day | B29: 6 | C29: h/day | D29: Per drawing: 20 m3/h x 6 h/day = 120 m3/day
A30: Operating days per month | B30: 30 | C30: days | D30: Assumed
A31: Electricity tariff (for estimate only) | B31: 0.509 | C31: RM/kWh | D31: Assumed TNB Tariff C1 energy charge; replace with actual tariff

Sheet Pump Sizing
A1: Pump Hydraulic Power and Motor kW Required
A2: P_hyd (kW) = rho x g x Q x H / (3,600 x 1,000). Shaft kW = P_hyd / pump eff. Motor = next standard IEC rating above shaft kW x margin.
A4: No. | B4: Tag | C4: Service | D4: Duty / Standby | E4: Flow Q (m3/h) | F4: Head H (m) | G4: Hydraulic power (kW) | H4: Pump eff. | I4: Shaft power (kW) | J4: Shaft x margin (kW) | K4: Calculated motor (kW) | L4: Drawing motor (kW) | M4: Design motor (kW) | N4: Motor eff. | O4: PF | P4: FLC (A) | Q4: Starter | R4: Starting current (A) | S4: Remarks
A5: 1 | B5: P-01 | C5: Raw Water Pump-1 (Duty) | D5: Duty | E5: 10 | F5: 30 | G5: =Inputs!$B$14*Inputs!$B$15*E5*F5/(3600*1000) -> 0.8175 | H5: =Inputs!$B$12 -> 0.65 | I5: =G5/H5 -> 1.2576923 | J5: =I5*Inputs!$B$13 -> 1.5092308 | K5: =INDEX(Inputs!$F$5:$F$19,COUNTIF(Inputs!$F$5:$F$19,"<"&J5)+1) -> 2.2 | L5: 5.5 | M5: =IF(Inputs!$B$27="Calculated",K5,L5) -> 5.5 | N5: =Inputs!$B$11 -> 0.896 | O5: =Inputs!$B$9 -> 0.85 | P5: =M5*1000/(SQRT(3)*Inputs!$B$6*N5*O5) -> 10.046783 | Q5: =IF(M5>=Inputs!$B$26,"Star-Delta","DOL") -> Star-Delta | R5: =P5*IF(Q5="DOL",Inputs!$B$24,Inputs!$B$25) -> 20.093566 | S5: Drawing: 10 m3/h, 25-30 m. Upper head used.
A6: 2 | B6: P-02 | C6: Raw Water Pump-2 (Standby) | D6: Standby | E6: 10 | F6: 30 | G6: =Inputs!$B$14*Inputs!$B$15*E6*F6/(3600*1000) -> 0.8175 | H6: =Inputs!$B$12 -> 0.65 | I6: =G6/H6 -> 1.2576923 | J6: =I6*Inputs!$B$13 -> 1.5092308 | K6: =INDEX(Inputs!$F$5:$F$19,COUNTIF(Inputs!$F$5:$F$19,"<"&J6)+1) -> 2.2 | L6: 5.5 | M6: =IF(Inputs!$B$27="Calculated",K6,L6) -> 5.5 | N6: =Inputs!$B$11 -> 0.896 | O6: =Inputs!$B$9 -> 0.85 | P6: =M6*1000/(SQRT(3)*Inputs!$B$6*N6*O6) -> 10.046783 | Q6: =IF(M6>=Inputs!$B$26,"Star-Delta","DOL") -> Star-Delta | R6: =P6*IF(Q6="DOL",Inputs!$B$24,Inputs!$B$25) -> 20.093566 | S6: Identical to P-01, 100% standby.
A7: 3 | B7: P-08 | C7: Backwash Pump (Duty) | D7: Duty | E7: 30 | F7: 30 | G7: =Inputs!$B$14*Inputs!$B$15*E7*F7/(3600*1000) -> 2.4525 | H7: =Inputs!$B$12 -> 0.65 | I7: =G7/H7 -> 3.7730769 | J7: =I7*Inputs!$B$13 -> 4.5276923 | K7: =INDEX(Inputs!$F$5:$F$19,COUNTIF(Inputs!$F$5:$F$19,"<"&J7)+1) -> 5.5 | L7: 5.5 | M7: =IF(Inputs!$B$27="Calculated",K7,L7) -> 5.5 | N7: =Inputs!$B$11 -> 0.896 | O7: =Inputs!$B$9 -> 0.85 | P7: =M7*1000/(SQRT(3)*Inputs!$B$6*N7*O7) -> 10.046783 | Q7: =IF(M7>=Inputs!$B$26,"Star-Delta","DOL") -> Star-Delta | R7: =P7*IF(Q7="DOL",Inputs!$B$24,Inputs!$B$25) -> 20.093566 | S7: Drawing: 25-30 m3/h, 25-30 m. Backwash flow 25-30 m3/h at 2.0 m/s.
A8: 4 | B8: P-11 | C8: Backwash Pump (Standby) | D8: Standby | E8: 30 | F8: 30 | G8: =Inputs!$B$14*Inputs!$B$15*E8*F8/(3600*1000) -> 2.4525 | H8: =Inputs!$B$12 -> 0.65 | I8: =G8/H8 -> 3.7730769 | J8: =I8*Inputs!$B$13 -> 4.5276923 | K8: =INDEX(Inputs!$F$5:$F$19,COUNTIF(Inputs!$F$5:$F$19,"<"&J8)+1) -> 5.5 | L8: 5.5 | M8: =IF(Inputs!$B$27="Calculated",K8,L8) -> 5.5 | N8: =Inputs!$B$11 -> 0.896 | O8: =Inputs!$B$9 -> 0.85 | P8: =M8*1000/(SQRT(3)*Inputs!$B$6*N8*O8) -> 10.046783 | Q8: =IF(M8>=Inputs!$B$26,"Star-Delta","DOL") -> Star-Delta | R8: =P8*IF(Q8="DOL",Inputs!$B$24,Inputs!$B$25) -> 20.093566 | S8: Identical to P-08, 100% standby.
A9: 5 | B9: P-09 | C9: Treated Water Pump | D9: Duty | E9: 12 | F9: 30 | G9: =Inputs!$B$14*Inputs!$B$15*E9*F9/(3600*1000) -> 0.981 | H9: =Inputs!$B$12 -> 0.65 | I9: =G9/H9 -> 1.5092308 | J9: =I9*Inputs!$B$13 -> 1.8110769 | K9: =INDEX(Inputs!$F$5:$F$19,COUNTIF(Inputs!$F$5:$F$19,"<"&J9)+1) -> 2.2 | L9: 5.5 | M9: =IF(Inputs!$B$27="Calculated",K9,L9) -> 5.5 | N9: =Inputs!$B$11 -> 0.896 | O9: =Inputs!$B$9 -> 0.85 | P9: =M9*1000/(SQRT(3)*Inputs!$B$6*N9*O9) -> 10.046783 | Q9: =IF(M9>=Inputs!$B$26,"Star-Delta","DOL") -> Star-Delta | R9: =P9*IF(Q9="DOL",Inputs!$B$24,Inputs!$B$25) -> 20.093566 | S9: Drawing: 10-12 m3/h, 25-30 m. Lifts to elevated tanks at 7.0 m plus DN90 rising main losses.
C11: Total installed motor kW (all pumps) | M11: =SUM(M5:M9) -> 27.5
C12: Total duty motor kW (standby excluded) | M12: =SUMIF(D5:D9,"Duty",M5:M9) -> 16.5
C13: Largest single motor (kW) | M13: =MAX(M5:M9) -> 5.5
A15: NOTES
A16: 1. Hydraulic power uses the upper end of the flow and head ranges on the drawing, which is conservative.
A17: 2. The calculated motor column shows the minimum standard IEC motor that satisfies shaft power x margin. The drawing specifies 5.5 kW for all five pumps.
A18: 3. The raw water and treated water pumps calculate to 2.2 kW. 5.5 kW motors give about 2.5x margin; this is acceptable if the vendor pump curve runs out to higher flow, but a 3 kW or 4 kW motor would reduce starting current and cost.
A19: 4. The backwash pumps calculate to 5.5 kW at 30 m3/h and 30 m, so the drawing rating is appropriate.
A20: 5. Change the 'Electrical design basis' cell on the Inputs sheet to 'Calculated' to re-size all feeders and the incoming supply on the calculated motors.
A21: 6. Standby pumps are excluded from maximum demand on the Incoming Supply sheet; they are electrically interlocked with their duty pump.

Sheet Load Schedule
A1: Load Schedule - Motor Control Centre and WTP Control DB
A2: Feeder sizing: FLC -> breaker (next standard size above FLC x factor) -> cable (ampacity after derating >= breaker) -> voltage drop check.
A4: Ckt | B4: Feeder / Load | C4: Load type | D4: Ph | E4: Qty | F4: Unit kW | G4: Connected kW | H4: PF | I4: Eff. | J4: FLC (A) | K4: Running (Y/N) | L4: Diversity | M4: Running input kW | N4: Running kVA | O4: Breaker factor | P4: Breaker calc (A) | Q4: Breaker selected (A) | R4: Breaker type | S4: Starter | T4: Cable length (m) | U4: Cable req. (A) | V4: Cable size (mm2) | W4: Cable rating (A) | X4: Volt drop (V) | Y4: Volt drop (%) | Z4: VD check / Remarks
A5: MCC-1 | B5: Raw Water Pump-1 (Duty) | C5: Motor | D5: 3 | E5: 1 | F5: ='Pump Sizing'!M5 -> 5.5 | G5: =E5*F5 -> 5.5 | H5: =IF(C5="Motor",Inputs!$B$9,Inputs!$B$10) -> 0.85 | I5: =IF(C5="Motor",Inputs!$B$11,1) -> 0.896 | J5: =IF(D5=3,G5*1000/(SQRT(3)*Inputs!$B$6*H5*I5),G5*1000/(Inputs!$B$8*H5*I5)) -> 10.046783 | K5: Y | L5: 1 | M5: =IF(K5="Y",G5*L5/I5,0) -> 6.1383929 | N5: =M5/H5 -> 7.2216387 | O5: =IF(C5="Motor",Inputs!$B$17,Inputs!$B$18) -> 2 | P5: =J5*O5 -> 20.093566 | Q5: =INDEX(Inputs!$H$5:$H$22,COUNTIF(Inputs!$H$5:$H$22,"<"&P5)+1) -> 25 | R5: MCCB 3P | S5: =IF(C5<>"Motor","-",IF(F5>=Inputs!$B$26,"Star-Delta","DOL")) -> Star-Delta | T5: 30 | U5: =Q5/Inputs!$B$19 -> 28.735632 | V5: =INDEX(Inputs!$J$5:$J$19,COUNTIF(Inputs!$K$5:$K$19,"<"&U5)+1) -> 2.5 | W5: =INDEX(Inputs!$K$5:$K$19,COUNTIF(Inputs!$K$5:$K$19,"<"&U5)+1) -> 30 | X5: =INDEX(Inputs!$L$5:$L$19,COUNTIF(Inputs!$K$5:$K$19,"<"&U5)+1)*J5*T5/1000 -> 5.4252629 | Y5: =X5/IF(D5=3,Inputs!$B$6,Inputs!$B$8) -> 0.013072923 | Z5: =IF(Y5<=IF(C5="Motor",Inputs!$B$20,Inputs!$B$21),"OK","EXCEEDS LIMIT - upsize cable")&" - "&"Star-Delta per drawing" -> OK - Star-Delta per drawing
A6: MCC-2 | B6: Raw Water Pump-2 (Standby) | C6: Motor | D6: 3 | E6: 1 | F6: ='Pump Sizing'!M6 -> 5.5 | G6: =E6*F6 -> 5.5 | H6: =IF(C6="Motor",Inputs!$B$9,Inputs!$B$10) -> 0.85 | I6: =IF(C6="Motor",Inputs!$B$11,1) -> 0.896 | J6: =IF(D6=3,G6*1000/(SQRT(3)*Inputs!$B$6*H6*I6),G6*1000/(Inputs!$B$8*H6*I6)) -> 10.046783 | K6: N | L6: 1 | M6: =IF(K6="Y",G6*L6/I6,0) -> 0 | N6: =M6/H6 -> 0 | O6: =IF(C6="Motor",Inputs!$B$17,Inputs!$B$18) -> 2 | P6: =J6*O6 -> 20.093566 | Q6: =INDEX(Inputs!$H$5:$H$22,COUNTIF(Inputs!$H$5:$H$22,"<"&P6)+1) -> 25 | R6: MCCB 3P | S6: =IF(C6<>"Motor","-",IF(F6>=Inputs!$B$26,"Star-Delta","DOL")) -> Star-Delta | T6: 30 | U6: =Q6/Inputs!$B$19 -> 28.735632 | V6: =INDEX(Inputs!$J$5:$J$19,COUNTIF(Inputs!$K$5:$K$19,"<"&U6)+1) -> 2.5 | W6: =INDEX(Inputs!$K$5:$K$19,COUNTIF(Inputs!$K$5:$K$19,"<"&U6)+1) -> 30 | X6: =INDEX(Inputs!$L$5:$L$19,COUNTIF(Inputs!$K$5:$K$19,"<"&U6)+1)*J6*T6/1000 -> 5.4252629 | Y6: =X6/IF(D6=3,Inputs!$B$6,Inputs!$B$8) -> 0.013072923 | Z6: =IF(Y6<=IF(C6="Motor",Inputs!$B$20,Inputs!$B$21),"OK","EXCEEDS LIMIT - upsize cable")&" - "&"Standby - interlocked with MCC-1" -> OK - Standby - interlocked with MCC-1
A7: MCC-3 | B7: Backwash Pump (Duty) | C7: Motor | D7: 3 | E7: 1 | F7: ='Pump Sizing'!M7 -> 5.5 | G7: =E7*F7 -> 5.5 | H7: =IF(C7="Motor",Inputs!$B$9,Inputs!$B$10) -> 0.85 | I7: =IF(C7="Motor",Inputs!$B$11,1) -> 0.896 | J7: =IF(D7=3,G7*1000/(SQRT(3)*Inputs!$B$6*H7*I7),G7*1000/(Inputs!$B$8*H7*I7)) -> 10.046783 | K7: Y | L7: 1 | M7: =IF(K7="Y",G7*L7/I7,0) -> 6.1383929 | N7: =M7/H7 -> 7.2216387 | O7: =IF(C7="Motor",Inputs!$B$17,Inputs!$B$18) -> 2 | P7: =J7*O7 -> 20.093566 | Q7: =INDEX(Inputs!$H$5:$H$22,COUNTIF(Inputs!$H$5:$H$22,"<"&P7)+1) -> 25 | R7: MCCB 3P | S7: =IF(C7<>"Motor","-",IF(F7>=Inputs!$B$26,"Star-Delta","DOL")) -> Star-Delta | T7: 30 | U7: =Q7/Inputs!$B$19 -> 28.735632 | V7: =INDEX(Inputs!$J$5:$J$19,COUNTIF(Inputs!$K$5:$K$19,"<"&U7)+1) -> 2.5 | W7: =INDEX(Inputs!$K$5:$K$19,COUNTIF(Inputs!$K$5:$K$19,"<"&U7)+1) -> 30 | X7: =INDEX(Inputs!$L$5:$L$19,COUNTIF(Inputs!$K$5:$K$19,"<"&U7)+1)*J7*T7/1000 -> 5.4252629 | Y7: =X7/IF(D7=3,Inputs!$B$6,Inputs!$B$8) -> 0.013072923 | Z7: =IF(Y7<=IF(C7="Motor",Inputs!$B$20,Inputs!$B$21),"OK","EXCEEDS LIMIT - upsize cable")&" - "&"Counted as running: backwash may overlap with raw water pumping (conservative)" -> OK - Counted as running: backwash may overlap with raw water pumping (conservative)
A8: MCC-4 | B8: Backwash Pump (Standby) | C8: Motor | D8: 3 | E8: 1 | F8: ='Pump Sizing'!M8 -> 5.5 | G8: =E8*F8 -> 5.5 | H8: =IF(C8="Motor",Inputs!$B$9,Inputs!$B$10) -> 0.85 | I8: =IF(C8="Motor",Inputs!$B$11,1) -> 0.896 | J8: =IF(D8=3,G8*1000/(SQRT(3)*Inputs!$B$6*H8*I8),G8*1000/(Inputs!$B$8*H8*I8)) -> 10.046783 | K8: N | L8: 1 | M8: =IF(K8="Y",G8*L8/I8,0) -> 0 | N8: =M8/H8 -> 0 | O8: =IF(C8="Motor",Inputs!$B$17,Inputs!$B$18) -> 2 | P8: =J8*O8 -> 20.093566 | Q8: =INDEX(Inputs!$H$5:$H$22,COUNTIF(Inputs!$H$5:$H$22,"<"&P8)+1) -> 25 | R8: MCCB 3P | S8: =IF(C8<>"Motor","-",IF(F8>=Inputs!$B$26,"Star-Delta","DOL")) -> Star-Delta | T8: 30 | U8: =Q8/Inputs!$B$19 -> 28.735632 | V8: =INDEX(Inputs!$J$5:$J$19,COUNTIF(Inputs!$K$5:$K$19,"<"&U8)+1) -> 2.5 | W8: =INDEX(Inputs!$K$5:$K$19,COUNTIF(Inputs!$K$5:$K$19,"<"&U8)+1) -> 30 | X8: =INDEX(Inputs!$L$5:$L$19,COUNTIF(Inputs!$K$5:$K$19,"<"&U8)+1)*J8*T8/1000 -> 5.4252629 | Y8: =X8/IF(D8=3,Inputs!$B$6,Inputs!$B$8) -> 0.013072923 | Z8: =IF(Y8<=IF(C8="Motor",Inputs!$B$20,Inputs!$B$21),"OK","EXCEEDS LIMIT - upsize cable")&" - "&"Standby - interlocked with MCC-3" -> OK - Standby - interlocked with MCC-3
A9: MCC-5 | B9: Treated Water Pump | C9: Motor | D9: 3 | E9: 1 | F9: ='Pump Sizing'!M9 -> 5.5 | G9: =E9*F9 -> 5.5 | H9: =IF(C9="Motor",Inputs!$B$9,Inputs!$B$10) -> 0.85 | I9: =IF(C9="Motor",Inputs!$B$11,1) -> 0.896 | J9: =IF(D9=3,G9*1000/(SQRT(3)*Inputs!$B$6*H9*I9),G9*1000/(Inputs!$B$8*H9*I9)) -> 10.046783 | K9: Y | L9: 1 | M9: =IF(K9="Y",G9*L9/I9,0) -> 6.1383929 | N9: =M9/H9 -> 7.2216387 | O9: =IF(C9="Motor",Inputs!$B$17,Inputs!$B$18) -> 2 | P9: =J9*O9 -> 20.093566 | Q9: =INDEX(Inputs!$H$5:$H$22,COUNTIF(Inputs!$H$5:$H$22,"<"&P9)+1) -> 25 | R9: MCCB 3P | S9: =IF(C9<>"Motor","-",IF(F9>=Inputs!$B$26,"Star-Delta","DOL")) -> Star-Delta | T9: 40 | U9: =Q9/Inputs!$B$19 -> 28.735632 | V9: =INDEX(Inputs!$J$5:$J$19,COUNTIF(Inputs!$K$5:$K$19,"<"&U9)+1) -> 2.5 | W9: =INDEX(Inputs!$K$5:$K$19,COUNTIF(Inputs!$K$5:$K$19,"<"&U9)+1) -> 30 | X9: =INDEX(Inputs!$L$5:$L$19,COUNTIF(Inputs!$K$5:$K$19,"<"&U9)+1)*J9*T9/1000 -> 7.2336839 | Y9: =X9/IF(D9=3,Inputs!$B$6,Inputs!$B$8) -> 0.017430564 | Z9: =IF(Y9<=IF(C9="Motor",Inputs!$B$20,Inputs!$B$21),"OK","EXCEEDS LIMIT - upsize cable")&" - "&"Longest run, to elevated tank side of shelter" -> OK - Longest run, to elevated tank side of shelter
A10: DB-1 | B10: Lighting | C10: Lighting | D10: 1 | E10: 1 | F10: 1.5 | G10: =E10*F10 -> 1.5 | H10: =IF(C10="Motor",Inputs!$B$9,Inputs!$B$10) -> 0.9 | I10: =IF(C10="Motor",Inputs!$B$11,1) -> 1 | J10: =IF(D10=3,G10*1000/(SQRT(3)*Inputs!$B$6*H10*I10),G10*1000/(Inputs!$B$8*H10*I10)) -> 6.9444444 | K10: Y | L10: =Inputs!$B$22 -> 0.8 | M10: =IF(K10="Y",G10*L10/I10,0) -> 1.2 | N10: =M10/H10 -> 1.3333333 | O10: =IF(C10="Motor",Inputs!$B$17,Inputs!$B$18) -> 1.25 | P10: =J10*O10 -> 8.6805556 | Q10: =INDEX(Inputs!$H$5:$H$22,COUNTIF(Inputs!$H$5:$H$22,"<"&P10)+1) -> 10 | R10: MCB 1P | S10: =IF(C10<>"Motor","-",IF(F10>=Inputs!$B$26,"Star-Delta","DOL")) -> - | T10: 25 | U10: =Q10/Inputs!$B$19 -> 11.494253 | V10: =INDEX(Inputs!$J$5:$J$19,COUNTIF(Inputs!$K$5:$K$19,"<"&U10)+1) -> 1.5 | W10: =INDEX(Inputs!$K$5:$K$19,COUNTIF(Inputs!$K$5:$K$19,"<"&U10)+1) -> 22 | X10: =INDEX(Inputs!$L$5:$L$19,COUNTIF(Inputs!$K$5:$K$19,"<"&U10)+1)*J10*T10/1000 -> 5.0347222 | Y10: =X10/IF(D10=3,Inputs!$B$6,Inputs!$B$8) -> 0.020978009 | Z10: =IF(Y10<=IF(C10="Motor",Inputs!$B$20,Inputs!$B$21),"OK","EXCEEDS LIMIT - upsize cable")&" - "&"Assumed 1.5 kW LED lighting (approx. 11 W/m2 x 132 m2). Drawing: MCB 1P 10A" -> OK - Assumed 1.5 kW LED lighting (approx. 11 W/m2 x 132 m2). Drawing: MCB 1P 10A
A11: DB-2 | B11: Socket outlets | C11: Small power | D11: 1 | E11: 1 | F11: 2 | G11: =E11*F11 -> 2 | H11: =IF(C11="Motor",Inputs!$B$9,Inputs!$B$10) -> 0.9 | I11: =IF(C11="Motor",Inputs!$B$11,1) -> 1 | J11: =IF(D11=3,G11*1000/(SQRT(3)*Inputs!$B$6*H11*I11),G11*1000/(Inputs!$B$8*H11*I11)) -> 9.2592593 | K11: Y | L11: =Inputs!$B$22 -> 0.8 | M11: =IF(K11="Y",G11*L11/I11,0) -> 1.6 | N11: =M11/H11 -> 1.7777778 | O11: =IF(C11="Motor",Inputs!$B$17,Inputs!$B$18) -> 1.25 | P11: =J11*O11 -> 11.574074 | Q11: =INDEX(Inputs!$H$5:$H$22,COUNTIF(Inputs!$H$5:$H$22,"<"&P11)+1) -> 16 | R11: MCB 1P | S11: =IF(C11<>"Motor","-",IF(F11>=Inputs!$B$26,"Star-Delta","DOL")) -> - | T11: 25 | U11: =Q11/Inputs!$B$19 -> 18.390805 | V11: =INDEX(Inputs!$J$5:$J$19,COUNTIF(Inputs!$K$5:$K$19,"<"&U11)+1) -> 1.5 | W11: =INDEX(Inputs!$K$5:$K$19,COUNTIF(Inputs!$K$5:$K$19,"<"&U11)+1) -> 22 | X11: =INDEX(Inputs!$L$5:$L$19,COUNTIF(Inputs!$K$5:$K$19,"<"&U11)+1)*J11*T11/1000 -> 6.712963 | Y11: =X11/IF(D11=3,Inputs!$B$6,Inputs!$B$8) -> 0.027970679 | Z11: =IF(Y11<=IF(C11="Motor",Inputs!$B$20,Inputs!$B$21),"OK","EXCEEDS LIMIT - upsize cable")&" - "&"Assumed 2.0 kW allowance. Drawing: MCB 1P 10A" -> OK - Assumed 2.0 kW allowance. Drawing: MCB 1P 10A
A12: DB-3 | B12: Chemical dosing pumps (PAC, Soda Ash, TCCA, C833/HEDP) | C12: Motor | D12: 1 | E12: 4 | F12: 0.12 | G12: =E12*F12 -> 0.48 | H12: =IF(C12="Motor",Inputs!$B$9,Inputs!$B$10) -> 0.85 | I12: =IF(C12="Motor",Inputs!$B$11,1) -> 0.896 | J12: =IF(D12=3,G12*1000/(SQRT(3)*Inputs!$B$6*H12*I12),G12*1000/(Inputs!$B$8*H12*I12)) -> 2.6260504 | K12: Y | L12: 1 | M12: =IF(K12="Y",G12*L12/I12,0) -> 0.53571429 | N12: =M12/H12 -> 0.6302521 | O12: =IF(C12="Motor",Inputs!$B$17,Inputs!$B$18) -> 2 | P12: =J12*O12 -> 5.2521008 | Q12: =INDEX(Inputs!$H$5:$H$22,COUNTIF(Inputs!$H$5:$H$22,"<"&P12)+1) -> 6 | R12: MCB 1P | S12: =IF(C12<>"Motor","-",IF(F12>=Inputs!$B$26,"Star-Delta","DOL")) -> DOL | T12: 20 | U12: =Q12/Inputs!$B$19 -> 6.8965517 | V12: =INDEX(Inputs!$J$5:$J$19,COUNTIF(Inputs!$K$5:$K$19,"<"&U12)+1) -> 1.5 | W12: =INDEX(Inputs!$K$5:$K$19,COUNTIF(Inputs!$K$5:$K$19,"<"&U12)+1) -> 22 | X12: =INDEX(Inputs!$L$5:$L$19,COUNTIF(Inputs!$K$5:$K$19,"<"&U12)+1)*J12*T12/1000 -> 1.5231092 | Y12: =X12/IF(D12=3,Inputs!$B$6,Inputs!$B$8) -> 0.0063462885 | Z12: =IF(Y12<=IF(C12="Motor",Inputs!$B$20,Inputs!$B$21),"OK","EXCEEDS LIMIT - upsize cable")&" - "&"Assumed 0.12 kW each diaphragm dosing pump. Drawing: MCB 1P 6A" -> OK - Assumed 0.12 kW each diaphragm dosing pump. Drawing: MCB 1P 6A
A13: DB-4 | B13: Agitators (chemical tanks) | C13: Motor | D13: 1 | E13: 4 | F13: 0.37 | G13: =E13*F13 -> 1.48 | H13: =IF(C13="Motor",Inputs!$B$9,Inputs!$B$10) -> 0.85 | I13: =IF(C13="Motor",Inputs!$B$11,1) -> 0.896 | J13: =IF(D13=3,G13*1000/(SQRT(3)*Inputs!$B$6*H13*I13),G13*1000/(Inputs!$B$8*H13*I13)) -> 8.0969888 | K13: Y | L13: 1 | M13: =IF(K13="Y",G13*L13/I13,0) -> 1.6517857 | N13: =M13/H13 -> 1.9432773 | O13: =IF(C13="Motor",Inputs!$B$17,Inputs!$B$18) -> 2 | P13: =J13*O13 -> 16.193978 | Q13: =INDEX(Inputs!$H$5:$H$22,COUNTIF(Inputs!$H$5:$H$22,"<"&P13)+1) -> 20 | R13: MCB 1P | S13: =IF(C13<>"Motor","-",IF(F13>=Inputs!$B$26,"Star-Delta","DOL")) -> DOL | T13: 20 | U13: =Q13/Inputs!$B$19 -> 22.988506 | V13: =INDEX(Inputs!$J$5:$J$19,COUNTIF(Inputs!$K$5:$K$19,"<"&U13)+1) -> 2.5 | W13: =INDEX(Inputs!$K$5:$K$19,COUNTIF(Inputs!$K$5:$K$19,"<"&U13)+1) -> 30 | X13: =INDEX(Inputs!$L$5:$L$19,COUNTIF(Inputs!$K$5:$K$19,"<"&U13)+1)*J13*T13/1000 -> 2.914916 | Y13: =X13/IF(D13=3,Inputs!$B$6,Inputs!$B$8) -> 0.012145483 | Z13: =IF(Y13<=IF(C13="Motor",Inputs!$B$20,Inputs!$B$21),"OK","EXCEEDS LIMIT - upsize cable")&" - "&"Assumed 0.37 kW each. Drawing: MCB 1P 6A" -> OK - Assumed 0.37 kW each. Drawing: MCB 1P 6A
A14: DB-5 | B14: Control panel, PLC, level sensors, residual chlorine analyser | C14: Small power | D14: 1 | E14: 1 | F14: 0.5 | G14: =E14*F14 -> 0.5 | H14: =IF(C14="Motor",Inputs!$B$9,Inputs!$B$10) -> 0.9 | I14: =IF(C14="Motor",Inputs!$B$11,1) -> 1 | J14: =IF(D14=3,G14*1000/(SQRT(3)*Inputs!$B$6*H14*I14),G14*1000/(Inputs!$B$8*H14*I14)) -> 2.3148148 | K14: Y | L14: 1 | M14: =IF(K14="Y",G14*L14/I14,0) -> 0.5 | N14: =M14/H14 -> 0.55555556 | O14: =IF(C14="Motor",Inputs!$B$17,Inputs!$B$18) -> 1.25 | P14: =J14*O14 -> 2.8935185 | Q14: =INDEX(Inputs!$H$5:$H$22,COUNTIF(Inputs!$H$5:$H$22,"<"&P14)+1) -> 6 | R14: MCB 1P | S14: =IF(C14<>"Motor","-",IF(F14>=Inputs!$B$26,"Star-Delta","DOL")) -> - | T14: 10 | U14: =Q14/Inputs!$B$19 -> 6.8965517 | V14: =INDEX(Inputs!$J$5:$J$19,COUNTIF(Inputs!$K$5:$K$19,"<"&U14)+1) -> 1.5 | W14: =INDEX(Inputs!$K$5:$K$19,COUNTIF(Inputs!$K$5:$K$19,"<"&U14)+1) -> 22 | X14: =INDEX(Inputs!$L$5:$L$19,COUNTIF(Inputs!$K$5:$K$19,"<"&U14)+1)*J14*T14/1000 -> 0.6712963 | Y14: =X14/IF(D14=3,Inputs!$B$6,Inputs!$B$8) -> 0.0027970679 | Z14: =IF(Y14<=IF(C14="Motor",Inputs!$B$20,Inputs!$B$21),"OK","EXCEEDS LIMIT - upsize cable")&" - "&"Not shown on drawing - added as assumed load for auto operation" -> OK - Not shown on drawing - added as assumed load for auto operation
A15: DB-6 | B15: Spare | C15: Small power | D15: 1 | E15: 1 | F15: 0.5 | G15: =E15*F15 -> 0.5 | H15: =IF(C15="Motor",Inputs!$B$9,Inputs!$B$10) -> 0.9 | I15: =IF(C15="Motor",Inputs!$B$11,1) -> 1 | J15: =IF(D15=3,G15*1000/(SQRT(3)*Inputs!$B$6*H15*I15),G15*1000/(Inputs!$B$8*H15*I15)) -> 2.3148148 | K15: N | L15: 1 | M15: =IF(K15="Y",G15*L15/I15,0) -> 0 | N15: =M15/H15 -> 0 | O15: =IF(C15="Motor",Inputs!$B$17,Inputs!$B$18) -> 1.25 | P15: =J15*O15 -> 2.8935185 | Q15: =INDEX(Inputs!$H$5:$H$22,COUNTIF(Inputs!$H$5:$H$22,"<"&P15)+1) -> 6 | R15: MCB 1P | S15: =IF(C15<>"Motor","-",IF(F15>=Inputs!$B$26,"Star-Delta","DOL")) -> - | T15: 20 | U15: =Q15/Inputs!$B$19 -> 6.8965517 | V15: =INDEX(Inputs!$J$5:$J$19,COUNTIF(Inputs!$K$5:$K$19,"<"&U15)+1) -> 1.5 | W15: =INDEX(Inputs!$K$5:$K$19,COUNTIF(Inputs!$K$5:$K$19,"<"&U15)+1) -> 22 | X15: =INDEX(Inputs!$L$5:$L$19,COUNTIF(Inputs!$K$5:$K$19,"<"&U15)+1)*J15*T15/1000 -> 1.3425926 | Y15: =X15/IF(D15=3,Inputs!$B$6,Inputs!$B$8) -> 0.0055941358 | Z15: =IF(Y15<=IF(C15="Motor",Inputs!$B$20,Inputs!$B$21),"OK","EXCEEDS LIMIT - upsize cable")&" - "&"Spare way. Drawing: MCB 1P 6A" -> OK - Spare way. Drawing: MCB 1P 6A
B16: TOTAL | G16: =SUM(G5:G15) -> 33.96 | J16: =N16*1000/(SQRT(3)*Inputs!$B$6) -> 38.821744 | M16: =SUM(M5:M15) -> 23.902679 | N16: =SUM(N5:N15) -> 27.905112
A18: LEGEND
A19: Blue = input. Green = linked from another sheet. Black = formula. Yellow fill = assumed load value not given on the drawing - confirm with vendor.
A20: FLC (A): 3-phase = kW x 1000 / (sqrt3 x V x PF x eff); 1-phase = kW x 1000 / (V_LN x PF x eff).
A21: Breaker: next standard rating above FLC x factor (2.0 for motors with starter overload relay, 1.25 otherwise).
A22: Cable: smallest size whose ampacity x derating factor is at least the breaker rating, so the breaker protects the cable.
A23: Voltage drop = mV/A/m x FLC x length / 1000, checked against the limit on the Inputs sheet. Single-phase circuits use the 4-core table values, which is conservative.
A24: Single-phase DB loads are to be distributed across R, Y, B phases as evenly as possible; the DB is a 3-phase board fed from the MCC.

Sheet Incoming Supply
A1: Incoming Power Supply Sizing - Main MCCB, Incoming Cable, TNB Supply and Standby Generator
A2: All values derive from the Load Schedule and Inputs sheets.
A4: Item | B4: Value | C4: Unit | D4: Formula / Basis
A5: A. CONNECTED AND RUNNING LOAD
A6: Total connected load (all feeders incl. standby) | B6: ='Load Schedule'!G16 -> 33.96 | C6: kW | D6: Sum of connected kW on Load Schedule
A7: Maximum demand - running input power | B7: ='Load Schedule'!M16 -> 23.902679 | C7: kW | D7: Running loads only, standby pumps excluded, diversity applied to lighting and small power, motor efficiency included
A8: Maximum demand - apparent power | B8: ='Load Schedule'!N16 -> 27.905112 | C8: kVA | D8: Sum of running kVA
A9: Overall power factor at maximum demand | B9: =IFERROR(B7/B8,0) -> 0.85656988 | C9: - | D9: kW / kVA
A10: Maximum demand current | B10: =B8*1000/(SQRT(3)*Inputs!$B$6) -> 38.821744 | C10: A | D10: kVA x 1000 / (sqrt3 x 415)
A11: B. INCOMING SUPPLY DESIGN CURRENT
A12: Spare capacity allowance | B12: =Inputs!$B$23 -> 0.25 | C12: - | D12: From Inputs
A13: Design current including spare capacity | B13: =B10*(1+B12) -> 48.527181 | C13: A | D13: Max demand current x (1 + spare)
A14: Largest motor FLC | B14: =MAX('Load Schedule'!J5:J9) -> 10.046783 | C14: A | D14: Largest of the MCC motor feeders
A15: Largest motor starting current (Star-Delta) | B15: =B14*Inputs!$B$25 -> 20.093566 | C15: A | D15: FLC x Star-Delta starting multiple
A16: Peak current during start of largest motor | B16: =B10-B14+B15 -> 48.868528 | C16: A | D16: Max demand current with the largest motor replaced by its starting current (other loads running). Main MCCB must not trip at this value.
A17: C. MAIN INCOMING MCCB
A18: Main MCCB required rating (next standard size) | B18: =INDEX(Inputs!$H$5:$H$22,COUNTIF(Inputs!$H$5:$H$22,"<"&B13)+1) -> 50 | C18: A | D18: Next standard rating above design current
A19: Main MCCB shown on drawing | B19: 225 | C19: A | D19: Drawing: Main MCCB 4P 225A
A20: Drawing MCCB utilisation at maximum demand | B20: =B10/B19 -> 0.17254109 | C20: % | D20: Max demand current / drawing MCCB rating
A21: Recommended main MCCB | B21: =MAX(B18,63) -> 63 | C21: A | D21: Calculated rating, but not less than 63 A (4-pole, with adjustable thermal setting, SPD Type 2 downstream, earth bar). Set thermal trip to design current.
A22: Assessment of drawing 225 A MCCB | B22: =IF(B19>=B18,"Adequate - oversized by "&TEXT(B19/B18,"0.0")&"x; acceptable if TNB connected load and metering CT are matched, otherwise reduce to recommended rating","UNDERSIZED - increase") -> Adequate - oversized by 4.5x; acceptable if TNB connected load and metering CT are matched, otherwise reduce to recommended rating | C22: - | D22: Comparison
A23: D. INCOMING CABLE (TNB meter board to MCC)
A24: Incoming cable length | B24: 25 | C24: m | D24: ASSUMED distance from TNB metering/main switch to MCC room. Edit.
A25: Required cable ampacity (recommended MCCB / derating) | B25: =B21/Inputs!$B$19 -> 72.413793 | C25: A | D25: Cable must be protected by the main MCCB
A26: Incoming cable size - Cu XLPE/SWA/PVC 4-core | B26: =INDEX(Inputs!$J$5:$J$19,COUNTIF(Inputs!$K$5:$K$19,"<"&B25)+1) -> 16 | C26: mm2 | D26: Smallest standard size meeting required ampacity
A27: Incoming cable rating | B27: =INDEX(Inputs!$K$5:$K$19,COUNTIF(Inputs!$K$5:$K$19,"<"&B25)+1) -> 94 | C27: A
A28: Voltage drop at design current | B28: =INDEX(Inputs!$L$5:$L$19,COUNTIF(Inputs!$K$5:$K$19,"<"&B25)+1)*B13*B24/1000 -> 3.3969026 | C28: V | D28: mV/A/m x design current x length
A29: Voltage drop | B29: =B28/Inputs!$B$6 -> 0.0081853076 | C29: % | D29: Limit for sub-main: see Inputs. Total from origin to motor terminals should stay within 5%.
A30: Voltage drop check | B30: =IF(B29<=Inputs!$B$20,"OK","EXCEEDS - upsize cable") -> OK | C30: -
A31: E. TNB SUPPLY APPLICATION
A32: Supply type | B32: 415 V, 3-phase, 4-wire, 50 Hz LV supply | C32: - | D32: Per drawing
A33: Declared maximum demand for TNB application | B33: =ROUNDUP(B8*(1+B12),0) -> 35 | C33: kVA | D33: Max demand kVA x (1 + spare), rounded up
A34: Connected load declared | B34: =ROUNDUP(B6,0) -> 34 | C34: kW
A35: Indicative tariff category | B35: =IF(B33<=100,"LV Commercial / Industrial (below 100 kVA class)","LV supply above 100 kVA - TNB may require CT metering") -> LV Commercial / Industrial (below 100 kVA class) | C35: - | D35: Indicative only - confirm with TNB regional office; actual tariff code depends on premises classification
A36: Energy consumption estimate | B36: =B7*Inputs!$B$29*Inputs!$B$30 -> 4302.4821 | C36: kWh/month | D36: Max demand kW x running hours/day x days/month (upper bound; backwash does not run all day)
A37: Energy cost estimate | B37: =B36*Inputs!$B$31 -> 2189.9634 | C37: RM/month | D37: kWh x assumed tariff (Inputs)
A38: F. STANDBY GENERATOR (optional, if required by client)
A39: Running load | B39: =B8 -> 27.905112 | C39: kVA | D39: Max demand kVA
A40: Starting kVA of largest motor (Star-Delta) | B40: =SQRT(3)*Inputs!$B$6*B15/1000 -> 14.443277 | C40: kVA | D40: sqrt3 x V x starting current / 1000
A41: Transient demand (running load minus largest motor plus its starting kVA) | B41: =B39-SQRT(3)*415*B14/1000+B40 -> 35.126751 | C41: kVA | D41: Worst case: largest motor starts with everything else running
...
